<?xml version="1.0"?>
<sdf version='1.11'>
  <world name='jetrover_world'>
    
    <!-- Physics settings -->
    <physics name='1ms' type='ignored'>
      <max_step_size>0.001</max_step_size>
      <real_time_factor>1.0</real_time_factor>
    </physics>

    <!-- Plugin for physics -->
    <plugin filename="gz-sim-physics-system" name="gz::sim::systems::Physics">
    </plugin>
    
    <!-- Plugin for user commands -->
    <plugin filename="gz-sim-user-commands-system" name="gz::sim::systems::UserCommands">
    </plugin>
    
    <!-- Plugin for scene broadcasting -->
    <plugin filename="gz-sim-scene-broadcaster-system" name="gz::sim::systems::SceneBroadcaster">
    </plugin>

    <!-- Lighting -->
    <light type="directional" name="sun">
      <cast_shadows>true</cast_shadows>
      <pose>0 0 10 0 0 0</pose>
      <diffuse>0.8 0.8 0.8 1</diffuse>
      <specular>0.2 0.2 0.2 1</specular>
      <attenuation>
        <range>1000</range>
        <constant>0.9</constant>
        <linear>0.01</linear>
        <quadratic>0.001</quadratic>
      </attenuation>
      <direction>-0.5 0.1 -0.9</direction>
    </light>

    <!-- Ground Plane -->
    <model name='ground_plane'>
      <static>true</static>
      <link name='link'>
        <collision name='collision'>
          <geometry>
            <plane>
              <normal>0 0 1</normal>
              <size>100 100</size>
            </plane>
          </geometry>
          <surface>
            <contact>
              <collide_bitmask>65535</collide_bitmask>
              <ode>
                <mu>100</mu>
                <mu2>50</mu2>
              </ode>
            </contact>
            <friction>
              <ode>
                <mu>100</mu>
                <mu2>50</mu2>
              </ode>
            </friction>
          </surface>
        </collision>
        <visual name='visual'>
          <cast_shadows>false</cast_shadows>
          <geometry>
            <plane>
              <normal>0 0 1</normal>
              <size>100 100</size>
            </plane>
          </geometry>
          <material>
            <ambient>0.8 0.8 0.8 1</ambient>
            <diffuse>0.8 0.8 0.8 1</diffuse>
            <specular>0 0 0 1</specular>
          </material>
        </visual>
      </link>
    </model>

    <!-- Your JetRover Model -->
    <model name='jetrover'>
      <!-- Position the robot slightly above ground -->
      <pose>0 0 0 0 0 0</pose>
      
      <!-- Add physics configuration -->
      <static>false</static>
      <self_collide>false</self_collide>
      
      <link name='base_footprint'>
        <inertial>
          <pose>-0.0067354832080828474 0.0001003476674163358 0.048982494169840282 0 0 0</pose>
          <mass>2.7044057052136559</mass>
          <inertia>
            <ixx>0.024835337117375289</ixx>
            <ixy>4.3450755915186453e-06</ixy>
            <ixz>0.0041271174593116092</ixz>
            <iyy>0.039391409050316177</iyy>
            <iyz>-2.0732748511495032e-05</iyz>
            <izz>0.033570101918370988</izz>
          </inertia>
        </inertial>
        <collision name='base_footprint_fixed_joint_lump__base_link_collision'>
          <pose>0 0 0.11609108215767459 0 0 0</pose>
          <geometry>
            <mesh>
              <scale>1 1 1</scale>
              <uri>meshes_1/mecanum/base_link_collision.stl</uri>
            </mesh>
          </geometry>
        </collision>
        <collision name='base_footprint_fixed_joint_lump__back_shell_black_link_collision_1'>
          <pose>-0.0080042302115637693 0.00018689841620892801 0.11609108215767459 0 0 0</pose>
          <geometry>
            <mesh>
              <scale>1 1 1</scale>
              <uri>meshes_1/common/back_shell_black_link_collision.stl</uri>
            </mesh>
          </geometry>
        </collision>
        <collision name='base_footprint_fixed_joint_lump__back_shell_green_link_collision_2'>
          <pose>-0.0080041999999999995 0.00018689999999999999 0.11609108215767459 0 0 0</pose>
          <geometry>
            <mesh>
              <scale>1 1 1</scale>
              <uri>meshes_1/common/back_shell_green_link_collision.stl</uri>
            </mesh>
          </geometry>
        </collision>
        <collision name='base_footprint_fixed_joint_lump__imu_link_collision_3'>
          <pose>0.0048415999999999997 0.011168000000000001 0.1103512821576746 3.1415926535897931 0 -1.5707963267948959</pose>
          <geometry>
            <mesh>
              <scale>1 1 1</scale>
              <uri>meshes_1/common/imu_link.stl</uri>
            </mesh>
          </geometry>
        </collision>
        <collision name='base_footprint_fixed_joint_lump__wheel_left_back_link_collision_4'>
          <pose>-0.0975130776687404 0.11212949919983201 0.048250000000000001 0 0 0</pose>
          <geometry>
            <mesh>
              <scale>1 1 1</scale>
              <uri>meshes_1/mecanum/wheel_left_back_link_collision.stl</uri>
            </mesh>
          </geometry>
        </collision>
        <collision name='base_footprint_fixed_joint_lump__wheel_left_front_link_collision_5'>
          <pose>0.097513076949966304 0.11212949984638999 0.048249999999999502 0 0 0</pose>
          <geometry>
            <mesh>
              <scale>1 1 1</scale>
              <uri>meshes_1/mecanum/wheel_left_front_link_collision.stl</uri>
            </mesh>
          </geometry>
        </collision>
        <collision name='base_footprint_fixed_joint_lump__wheel_right_back_link_collision_6'>
          <pose>-0.097513076949966998 -0.11212949984638999 0.048250000000000209 0 0 0</pose>
          <geometry>
            <mesh>
              <scale>1 1 1</scale>
              <uri>meshes_1/mecanum/wheel_right_back_link_collision.stl</uri>
            </mesh>
          </geometry>
        </collision>
        <collision name='base_footprint_fixed_joint_lump__wheel_right_front_link_collision_7'>
          <pose>0.097513077668739803 -0.11212949919983201 0.048249999999999897 0 0 0</pose>
          <geometry>
            <mesh>
              <scale>1 1 1</scale>
              <uri>meshes_1/mecanum/wheel_right_front_link_collision.stl</uri>
            </mesh>
          </geometry>
        </collision>
        <visual name='base_footprint_fixed_joint_lump__base_link_visual'>
          <pose>0 0 0.11609108215767459 0 0 0</pose>
          <geometry>
            <mesh>
              <scale>1 1 1</scale>
              <uri>file:///home/sukritchopra/ros2_ws/install/jetrover_description/share/jetrover_description/meshes/mecanum/base_link.stl</uri>
            </mesh>
          </geometry>
          <material>
            <diffuse>0.5 1 0.5 1</diffuse>
            <ambient>0.5 1 0.5 1</ambient>
          </material>
        </visual>
        <visual name='base_footprint_fixed_joint_lump__back_shell_black_link_visual_1'>
          <pose>-0.0080042302115637693 0.00018689841620892801 0.11609108215767459 0 0 0</pose>
          <geometry>
            <mesh>
              <scale>1 1 1</scale>
              <uri>meshes_1/common/back_shell_black_link.stl</uri>
            </mesh>
          </geometry>
          <material>
            <diffuse>0.125 0.125 0.125 1</diffuse>
            <ambient>0.125 0.125 0.125 1</ambient>
          </material>
        </visual>
        <visual name='base_footprint_fixed_joint_lump__back_shell_green_link_visual_2'>
          <pose>-0.0080041999999999995 0.00018689999999999999 0.11609108215767459 0 0 0</pose>
          <geometry>
            <mesh>
              <scale>1 1 1</scale>
              <uri>meshes_1/common/back_shell_green_link.stl</uri>
            </mesh>
          </geometry>
          <material>
            <diffuse>0.5 1 0.5 1</diffuse>
            <ambient>0.5 1 0.5 1</ambient>
          </material>
        </visual>
        <visual name='base_footprint_fixed_joint_lump__imu_link_visual_3'>
          <pose>0.0048415999999999997 0.011168000000000001 0.1103512821576746 3.1415926535897931 0 -1.5707963267948959</pose>
          <geometry>
            <mesh>
              <scale>1 1 1</scale>
              <uri>meshes_1/common/imu_link.stl</uri>
            </mesh>
          </geometry>
          <material>
            <diffuse>0.125 0.125 0.125 1</diffuse>
            <ambient>0.125 0.125 0.125 1</ambient>
          </material>
        </visual>
        <visual name='base_footprint_fixed_joint_lump__lidar_link_visual_4'>
          <pose>0.090003485935320399 0 0.15661065957563 0 0 0</pose>
          <geometry>
            <mesh>
              <scale>1 1 1</scale>
              <uri>meshes_1/common/lidar_link.stl</uri>
            </mesh>
          </geometry>
          <material>
            <diffuse>0.125 0.125 0.125 1</diffuse>
            <ambient>0.125 0.125 0.125 1</ambient>
          </material>
        </visual>
        <visual name='base_footprint_fixed_joint_lump__wheel_left_back_link_visual_5'>
          <pose>-0.0975130776687404 0.11212949919983201 0.048250000000000001 0 0 0</pose>
          <geometry>
            <mesh>
              <scale>1 1 1</scale>
              <uri>meshes_1/mecanum/wheel_left_back_link.stl</uri>
            </mesh>
          </geometry>
          <material>
            <diffuse>0.125 0.125 0.125 1</diffuse>
            <ambient>0.125 0.125 0.125 1</ambient>
          </material>
        </visual>
        <visual name='base_footprint_fixed_joint_lump__wheel_left_front_link_visual_6'>
          <pose>0.097513076949966304 0.11212949984638999 0.048249999999999502 0 0 0</pose>
          <geometry>
            <mesh>
              <scale>1 1 1</scale>
              <uri>meshes_1/mecanum/wheel_left_front_link.stl</uri>
            </mesh>
          </geometry>
          <material>
            <diffuse>0.125 0.125 0.125 1</diffuse>
            <ambient>0.125 0.125 0.125 1</ambient>
          </material>
        </visual>
        <visual name='base_footprint_fixed_joint_lump__wheel_right_back_link_visual_7'>
          <pose>-0.097513076949966998 -0.11212949984638999 0.048250000000000209 0 0 0</pose>
          <geometry>
            <mesh>
              <scale>1 1 1</scale>
              <uri>meshes_1/mecanum/wheel_right_back_link.stl</uri>
            </mesh>
          </geometry>
          <material>
            <diffuse>0.125 0.125 0.125 1</diffuse>
            <ambient>0.125 0.125 0.125 1</ambient>
          </material>
        </visual>
        <visual name='base_footprint_fixed_joint_lump__wheel_right_front_link_visual_8'>
          <pose>0.097513077668739803 -0.11212949919983201 0.048249999999999897 0 0 0</pose>
          <geometry>
            <mesh>
              <scale>1 1 1</scale>
              <uri>meshes_1/mecanum/wheel_right_front_link.stl</uri>
            </mesh>
          </geometry>
          <material>
            <diffuse>0.125 0.125 0.125 1</diffuse>
            <ambient>0.125 0.125 0.125 1</ambient>
          </material>
        </visual>
      </link>
      <joint name='joint1' type='revolute'>
        <pose relative_to='base_footprint'>0.0251328065010765 0 0.19349377025312589 0 0 0</pose>
        <parent>base_footprint</parent>
        <child>link1</child>
        <axis>
          <xyz>0 0 -1</xyz>
          <limit>
            <lower>-2.0899999999999999</lower>
            <upper>2.0899999999999999</upper>
            <effort>1000</effort>
            <velocity>10</velocity>
          </limit>
          <dynamics>
            <spring_reference>0</spring_reference>
            <spring_stiffness>0</spring_stiffness>
          </dynamics>
        </axis>
      </joint>
      <link name='link1'>
        <pose relative_to='joint1'>0 0 0 0 0 0</pose>
        <inertial>
          <pose>8.4882317065151008e-05 -0.0018903126840200471 0.020339854275225711 0 0 0</pose>
          <mass>0.030629351759666201</mass>
          <inertia>
            <ixx>5.9254568915084221e-06</ixx>
            <ixy>-1.7073764982422979e-09</ixy>
            <ixz>1.179843003882826e-09</ixz>
            <iyy>5.2110986859518246e-06</iyy>
            <iyz>3.1259704103886081e-07</iyz>
            <izz>3.394062289608808e-06</izz>
          </inertia>
        </inertial>
        <collision name='link1_collision'>
          <pose>0 0 0 0 0 0</pose>
          <geometry>
            <mesh>
              <scale>1 1 1</scale>
              <uri>meshes_1/arm/link1.STL</uri>
            </mesh>
          </geometry>
        </collision>
        <collision name='link1_fixed_joint_lump__servo_link1_collision_1'>
          <pose>0 0 0 0 0 0</pose>
          <geometry>
            <mesh>
              <scale>1 1 1</scale>
              <uri>meshes_1/arm/servo_link1_collision.stl</uri>
            </mesh>
          </geometry>
        </collision>
        <visual name='link1_visual'>
          <pose>0 0 0 0 0 0</pose>
          <geometry>
            <mesh>
              <scale>1 1 1</scale>
              <uri>meshes_1/arm/link1.STL</uri>
            </mesh>
          </geometry>
          <material>
            <diffuse>0.5 1 0.5 1</diffuse>
            <ambient>0.5 1 0.5 1</ambient>
          </material>
        </visual>
        <visual name='link1_fixed_joint_lump__servo_link1_visual_1'>
          <pose>0 0 0 0 0 0</pose>
          <geometry>
            <mesh>
              <scale>1 1 1</scale>
              <uri>meshes_1/arm/servo_link1.STL</uri>
            </mesh>
          </geometry>
          <material>
            <diffuse>0.125 0.125 0.125 1</diffuse>
            <ambient>0.125 0.125 0.125 1</ambient>
          </material>
        </visual>
      </link>
      <joint name='joint2' type='revolute'>
        <pose relative_to='link1'>0 0 0.0338648012164686 0 0 0</pose>
        <parent>link1</parent>
        <child>link2</child>
        <axis>
          <xyz>0 1 0</xyz>
          <limit>
            <lower>-2.0899999999999999</lower>
            <upper>2.0899999999999999</upper>
            <effort>1000</effort>
            <velocity>10</velocity>
          </limit>
          <dynamics>
            <spring_reference>0</spring_reference>
            <spring_stiffness>0</spring_stiffness>
          </dynamics>
        </axis>
      </joint>
      <link name='link2'>
        <pose relative_to='joint2'>0 0 0 0 0 0</pose>
        <inertial>
          <pose>0.00015629957042515699 -0.00045511369991391599 0.071772702851197495 0 0 0</pose>
          <mass>0.0329250074531705</mass>
          <inertia>
            <ixx>3.9162096617403702e-05</ixx>
            <ixy>-5.45461883923424e-11</ixy>
            <ixz>-1.84994427464167e-07</ixz>
            <iyy>3.0845356229789902e-05</iyy>
            <iyz>3.5881427402197002e-09</iyz>
            <izz>1.1508190097598299e-05</izz>
          </inertia>
        </inertial>
        <collision name='link2_collision'>
          <pose>0 0 0 0 0 0</pose>
          <geometry>
            <mesh>
              <scale>1 1 1</scale>
              <uri>meshes_1/arm/link2_collision.stl</uri>
            </mesh>
          </geometry>
        </collision>
        <visual name='link2_visual'>
          <pose>0 0 0 0 0 0</pose>
          <geometry>
            <mesh>
              <scale>1 1 1</scale>
              <uri>meshes_1/arm/link2.STL</uri>
            </mesh>
          </geometry>
          <material>
            <diffuse>0.5 1 0.5 1</diffuse>
            <ambient>0.5 1 0.5 1</ambient>
          </material>
        </visual>
      </link>
      <joint name='joint3' type='revolute'>
        <pose relative_to='link2'>0 0 0.12941644639479699 0 0 0</pose>
        <parent>link2</parent>
        <child>link3</child>
        <axis>
          <xyz>0 1 0</xyz>
          <limit>
            <lower>-2.0899999999999999</lower>
            <upper>2.0899999999999999</upper>
            <effort>1000</effort>
            <velocity>10</velocity>
          </limit>
          <dynamics>
            <spring_reference>0</spring_reference>
            <spring_stiffness>0</spring_stiffness>
          </dynamics>
        </axis>
      </joint>
      <link name='link3'>
        <pose relative_to='joint3'>0 0 0 0 0 0</pose>
        <inertial>
          <pose>0.00012845644092569799 -0.00076142462273371704 0.071772743785429 0 0 0</pose>
          <mass>0.0329250074463074</mass>
          <inertia>
            <ixx>3.91621699579612e-05</ixx>
            <ixy>-5.4009753055806201e-11</ixy>
            <ixz>-1.7378665251201299e-07</ixz>
            <iyy>3.0845196992023903e-05</iyy>
            <iyz>3.6387423652222298e-09</iyz>
            <izz>1.15078234912494e-05</izz>
          </inertia>
        </inertial>
        <collision name='link3_collision'>
          <pose>0 0 0 0 0 0</pose>
          <geometry>
            <mesh>
              <scale>1 1 1</scale>
              <uri>meshes_1/arm/link3_collision.stl</uri>
            </mesh>
          </geometry>
        </collision>
        <visual name='link3_visual'>
          <pose>0 0 0 0 0 0</pose>
          <geometry>
            <mesh>
              <scale>1 1 1</scale>
              <uri>meshes_1/arm/link3.STL</uri>
            </mesh>
          </geometry>
          <material>
            <diffuse>0.5 1 0.5 1</diffuse>
            <ambient>0.5 1 0.5 1</ambient>
          </material>
        </visual>
      </link>
      <joint name='joint4' type='revolute'>
        <pose relative_to='link3'>0 0 0.12944463118656899 0 0 0</pose>
        <parent>link3</parent>
        <child>link4</child>
        <axis>
          <xyz>0 1 0</xyz>
          <limit>
            <lower>-2.0899999999999999</lower>
            <upper>2.0899999999999999</upper>
            <effort>1000</effort>
            <velocity>10</velocity>
          </limit>
          <dynamics>
            <spring_reference>0</spring_reference>
            <spring_stiffness>0</spring_stiffness>
          </dynamics>
        </axis>
      </joint>
      <link name='link4'>
        <pose relative_to='joint4'>0 0 0 0 0 0</pose>
        <inertial>
          <pose>-0.024155385718921799 0.0003017349751323721 0.048529459632962173 0 0 0</pose>
          <mass>0.034930330045039162</mass>
          <inertia>
            <ixx>3.5210229125809753e-05</ixx>
            <ixy>1.013027133785351e-07</ixy>
            <ixz>1.5667877911856121e-05</ixz>
            <iyy>5.5524620335933228e-05</iyy>
            <iyz>-6.19231011536335e-08</iyz>
            <izz>3.3657929512902879e-05</izz>
          </inertia>
        </inertial>
        <collision name='link4_collision'>
          <pose>0 0 0 0 0 0</pose>
          <geometry>
            <mesh>
              <scale>1 1 1</scale>
              <uri>meshes_1/arm/link4_collision.stl</uri>
            </mesh>
          </geometry>
        </collision>
        <collision name='link4_fixed_joint_lump__camera_connect_link_collision_1'>
          <pose>-0.050706026697764403 0 0.0505384841187764 0 0 -1.5707963267948899</pose>
          <geometry>
            <mesh>
              <scale>1 1 1</scale>
              <uri>meshes_1/arm/camera_connect_link.STL</uri>
            </mesh>
          </geometry>
        </collision>
        <collision name='link4_fixed_joint_lump__depth_cam_link_collision_2'>
          <pose>-0.050706026697764403 0 0.065013484118776402 6.9084068182086093e-15 -1.5707963267948966 0</pose>
          <geometry>
            <mesh>
              <scale>1 1 1</scale>
              <uri>meshes_1/arm/depth_cam_link_collision.stl</uri>
            </mesh>
          </geometry>
        </collision>
        <collision name='link4_fixed_joint_lump__servo_link2_collision_3'>
          <pose>0 0 0.054483333950367398 0 0 0</pose>
          <geometry>
            <mesh>
              <scale>1 1 1</scale>
              <uri>meshes_1/arm/servo_link2_collision.stl</uri>
            </mesh>
          </geometry>
        </collision>
        <visual name='link4_visual'>
          <pose>0 0 0 0 0 0</pose>
          <geometry>
            <mesh>
              <scale>1 1 1</scale>
              <uri>meshes_1/arm/link4.STL</uri>
            </mesh>
          </geometry>
          <material>
            <diffuse>0.5 1 0.5 1</diffuse>
            <ambient>0.5 1 0.5 1</ambient>
          </material>
        </visual>
        <visual name='link4_fixed_joint_lump__camera_connect_link_visual_1'>
          <pose>-0.050706026697764403 0 0.0505384841187764 0 0 -1.5707963267948899</pose>
          <geometry>
            <mesh>
              <scale>1 1 1</scale>
              <uri>meshes_1/arm/camera_connect_link.STL</uri>
            </mesh>
          </geometry>
          <material>
            <diffuse>0.125 0.125 0.125 1</diffuse>
            <ambient>0.125 0.125 0.125 1</ambient>
          </material>
        </visual>
        <visual name='link4_fixed_joint_lump__depth_cam_link_visual_2'>
          <pose>-0.050706026697764403 0 0.065013484118776402 6.9084068182086093e-15 -1.5707963267948966 0</pose>
          <geometry>
            <mesh>
              <scale>1 1 1</scale>
              <uri>meshes_1/arm/depth_cam_link.STL</uri>
            </mesh>
          </geometry>
          <material>
            <diffuse>0.941250026 0.941250026 0.941250026 1</diffuse>
            <ambient>0.941250026 0.941250026 0.941250026 1</ambient>
          </material>
        </visual>
        <visual name='link4_fixed_joint_lump__servo_link2_visual_3'>
          <pose>0 0 0.054483333950367398 0 0 0</pose>
          <geometry>
            <mesh>
              <scale>1 1 1</scale>
              <uri>meshes_1/arm/servo_link2.STL</uri>
            </mesh>
          </geometry>
          <material>
            <diffuse>0.125 0.125 0.125 1</diffuse>
            <ambient>0.125 0.125 0.125 1</ambient>
          </material>
        </visual>
      </link>
      <joint name='joint5' type='revolute'>
        <pose relative_to='link4'>0 0 0.054483333950367398 0 0 0</pose>
        <parent>link4</parent>
        <child>link5</child>
        <axis>
          <xyz>0 0 -1</xyz>
          <limit>
            <lower>-2.0899999999999999</lower>
            <upper>2.0899999999999999</upper>
            <effort>1000</effort>
            <velocity>10</velocity>
          </limit>
          <dynamics>
            <spring_reference>0</spring_reference>
            <spring_stiffness>0</spring_stiffness>
          </dynamics>
        </axis>
      </joint>
      <link name='link5'>
        <pose relative_to='joint5'>0 0 0 0 0 0</pose>
        <inertial>
          <pose>0.013745583285676721 -0.0029797500659027461 0.029288990452975349 0 0 0</pose>
          <mass>0.01851660201761849</mass>
          <inertia>
            <ixx>4.8746350374566861e-06</ixx>
            <ixy>1.664776163181491e-08</ixy>
            <ixz>-3.9064646511571869e-07</ixz>
            <iyy>2.5142752233430748e-06</iyy>
            <iyz>1.050404679511314e-07</iyz>
            <izz>3.519823257486964e-06</izz>
          </inertia>
        </inertial>
        <collision name='link5_collision'>
          <pose>0 0 0 0 0 0</pose>
          <geometry>
            <mesh>
              <scale>1 1 1</scale>
              <uri>meshes_1/arm/link5.STL</uri>
            </mesh>
          </geometry>
        </collision>
        <collision name='link5_fixed_joint_lump__gripper_link_collision_1'>
          <pose>0 0 0.0054387999999999997 0 0 0</pose>
          <geometry>
            <mesh>
              <scale>1 1 1</scale>
              <uri>meshes_1/arm/gripper_link_collision.stl</uri>
            </mesh>
          </geometry>
        </collision>
        <visual name='link5_visual'>
          <pose>0 0 0 0 0 0</pose>
          <geometry>
            <mesh>
              <scale>1 1 1</scale>
              <uri>meshes_1/arm/link5.STL</uri>
            </mesh>
          </geometry>
          <material>
            <diffuse>0.125 0.125 0.125 1</diffuse>
            <ambient>0.125 0.125 0.125 1</ambient>
          </material>
        </visual>
        <visual name='link5_fixed_joint_lump__gripper_link_visual_1'>
          <pose>0 0 0.0054387999999999997 0 0 0</pose>
          <geometry>
            <mesh>
              <scale>1 1 1</scale>
              <uri>meshes_1/arm/gripper_link.STL</uri>
            </mesh>
          </geometry>
          <material>
            <diffuse>0.125 0.125 0.125 1</diffuse>
            <ambient>0.125 0.125 0.125 1</ambient>
          </material>
        </visual>
      </link>
      <joint name='l_in_joint' type='revolute'>
        <pose relative_to='link5'>-0.0071622999999999999 0.0049402999999999999 0.051457799999999998 0 0 0</pose>
        <parent>link5</parent>
        <child>l_in_link</child>
        <axis>
          <xyz>0.99995999999999996 0.0046982999999999999 -0.0070438999999999996</xyz>
          <mimic joint='r_joint'>
            <multiplier>-1</multiplier>
            <offset>0</offset>
            <reference>0</reference>
          </mimic>
          <limit>
            <lower>-1.5700000000000001</lower>
            <upper>1.5700000000000001</upper>
            <effort>1000</effort>
            <velocity>10</velocity>
          </limit>
          <dynamics>
            <spring_reference>0</spring_reference>
            <spring_stiffness>0</spring_stiffness>
          </dynamics>
        </axis>
      </joint>
      <link name='l_in_link'>
        <pose relative_to='l_in_joint'>0 0 0 0 0 0</pose>
        <inertial>
          <pose>0.0061019181206524503 2.9145913289670801e-05 0.0144573768632076 0 0 0</pose>
          <mass>0.000776872870694597</mass>
          <inertia>
            <ixx>9.87455572181138e-08</ixx>
            <ixy>5.0634092847572699e-12</ixy>
            <ixz>-6.7968564625618604e-10</ixz>
            <iyy>9.7663514845220301e-08</iyy>
            <iyz>-6.1211590832379402e-12</iyz>
            <izz>2.2569536475165801e-09</izz>
          </inertia>
        </inertial>
        <collision name='l_in_link_collision'>
          <pose>0 0 0 0 0 0</pose>
          <geometry>
            <mesh>
              <scale>1 1 1</scale>
              <uri>meshes_1/gripper/l_in_link.STL</uri>
            </mesh>
          </geometry>
        </collision>
        <visual name='l_in_link_visual'>
          <pose>0 0 0 0 0 0</pose>
          <geometry>
            <mesh>
              <scale>1 1 1</scale>
              <uri>meshes_1/gripper/l_in_link.STL</uri>
            </mesh>
          </geometry>
          <material>
            <diffuse>0.125 0.125 0.125 1</diffuse>
            <ambient>0.125 0.125 0.125 1</ambient>
          </material>
        </visual>
      </link>
      <joint name='l_out_joint' type='revolute'>
        <pose relative_to='l_in_link'>0.00020426999999999999 0 0.028999 0 0 0</pose>
        <parent>l_in_link</parent>
        <child>l_out_link</child>
        <axis>
          <xyz>0.99995999999999996 0.0046982999999999999 -0.0070438999999999996</xyz>
          <mimic joint='r_joint'>
            <multiplier>1</multiplier>
            <offset>0</offset>
            <reference>0</reference>
          </mimic>
          <limit>
            <lower>-1.5700000000000001</lower>
            <upper>1.5700000000000001</upper>
            <effort>1000</effort>
            <velocity>10</velocity>
          </limit>
          <dynamics>
            <spring_reference>0</spring_reference>
            <spring_stiffness>0</spring_stiffness>
          </dynamics>
        </axis>
      </joint>
      <link name='l_out_link'>
        <pose relative_to='l_out_joint'>0 0 0 0 0 0</pose>
        <inertial>
          <pose>0.0060240783651857701 0.0014461936314294 0.0096121404143418906 0 0 0</pose>
          <mass>0.0038473590828112399</mass>
          <inertia>
            <ixx>8.77337978935691e-07</ixx>
            <ixy>1.36760329013846e-09</ixy>
            <ixz>-6.9462127438421e-09</ixz>
            <iyy>8.1964879200802704e-07</iyy>
            <iyz>1.5617729472792301e-07</iyz>
            <izz>7.0687486597802998e-08</izz>
          </inertia>
        </inertial>
        <collision name='l_out_link_collision'>
          <pose>0 0 0 0 0 0</pose>
          <geometry>
            <mesh>
              <scale>1 1 1</scale>
              <uri>meshes_1/gripper/l_out_link.STL</uri>
            </mesh>
          </geometry>
        </collision>
        <visual name='l_out_link_visual'>
          <pose>0 0 0 0 0 0</pose>
          <geometry>
            <mesh>
              <scale>1 1 1</scale>
              <uri>meshes_1/gripper/l_out_link.STL</uri>
            </mesh>
          </geometry>
          <material>
            <diffuse>0.125 0.125 0.125 1</diffuse>
            <ambient>0.125 0.125 0.125 1</ambient>
          </material>
        </visual>
      </link>
      <joint name='l_joint' type='revolute'>
        <pose relative_to='link5'>-0.0073352000000000001 0.013977 0.032495799999999998 0 0 0</pose>
        <parent>link5</parent>
        <child>l_link</child>
        <axis>
          <xyz>0.99997000000000003 0.0055811000000000003 -0.0058396999999999998</xyz>
          <mimic joint='r_joint'>
            <multiplier>-1</multiplier>
            <offset>0</offset>
            <reference>0</reference>
          </mimic>
          <limit>
            <lower>-1.5700000000000001</lower>
            <upper>1.5700000000000001</upper>
            <effort>1000</effort>
            <velocity>10</velocity>
          </limit>
          <dynamics>
            <spring_reference>0</spring_reference>
            <spring_stiffness>0</spring_stiffness>
          </dynamics>
        </axis>
      </joint>
      <link name='l_link'>
        <pose relative_to='l_joint'>0 0 0 0 0 0</pose>
        <inertial>
          <pose>0.0015384031888858 -0.00040323272684767401 0.00579759783012201 0 0 0</pose>
          <mass>0.0021892493318732202</mass>
          <inertia>
            <ixx>4.0534152698165002e-07</ixx>
            <ixy>3.6007782749450302e-10</ixy>
            <ixz>-1.99675888093364e-09</ixz>
            <iyy>3.3122217418185201e-07</iyy>
            <iyz>-8.7933775825091693e-09</iyz>
            <izz>7.7431958264291705e-08</izz>
          </inertia>
        </inertial>
        <collision name='l_link_collision'>
          <pose>0 0 0 0 0 0</pose>
          <geometry>
            <mesh>
              <scale>1 1 1</scale>
              <uri>meshes_1/gripper/l_link.STL</uri>
            </mesh>
          </geometry>
        </collision>
        <visual name='l_link_visual'>
          <pose>0 0 0 0 0 0</pose>
          <geometry>
            <mesh>
              <scale>1 1 1</scale>
              <uri>meshes_1/gripper/l_link.STL</uri>
            </mesh>
          </geometry>
          <material>
            <diffuse>0.125 0.125 0.125 1</diffuse>
            <ambient>0.125 0.125 0.125 1</ambient>
          </material>
        </visual>
      </link>
      <joint name='r_in_joint' type='revolute'>
        <pose relative_to='link5'>-0.0071622999999999999 -0.0049430000000000003 0.051457799999999998 0 0 0</pose>
        <parent>link5</parent>
        <child>r_in_link</child>
        <axis>
          <xyz>-0.99995999999999996 0.0046987000000000001 0.0070435999999999997</xyz>
          <mimic joint='r_joint'>
            <multiplier>-1</multiplier>
            <offset>0</offset>
            <reference>0</reference>
          </mimic>
          <limit>
            <lower>-1.5700000000000001</lower>
            <upper>1.5700000000000001</upper>
            <effort>1000</effort>
            <velocity>10</velocity>
          </limit>
          <dynamics>
            <spring_reference>0</spring_reference>
            <spring_stiffness>0</spring_stiffness>
          </dynamics>
        </axis>
      </joint>
      <link name='r_in_link'>
        <pose relative_to='r_in_joint'>0 0 0 0 0 0</pose>
        <inertial>
          <pose>0.0061019181206500598 -2.8192469006870501e-05 0.014457378753895699 0 0 0</pose>
          <mass>0.00077687287069452197</mass>
          <inertia>
            <ixx>9.8746566817120394e-08</ixx>
            <ixy>-5.1117380810663599e-12</ixy>
            <ixz>-6.7969240619170703e-10</ixz>
            <iyy>9.7664293636848998e-08</iyy>
            <iyz>-5.1401880014949702e-13</iyz>
            <izz>2.2571845877848701e-09</izz>
          </inertia>
        </inertial>
        <collision name='r_in_link_collision'>
          <pose>0 0 0 0 0 0</pose>
          <geometry>
            <mesh>
              <scale>1 1 1</scale>
              <uri>meshes_1/gripper/r_in_link.STL</uri>
            </mesh>
          </geometry>
        </collision>
        <visual name='r_in_link_visual'>
          <pose>0 0 0 0 0 0</pose>
          <geometry>
            <mesh>
              <scale>1 1 1</scale>
              <uri>meshes_1/gripper/r_in_link.STL</uri>
            </mesh>
          </geometry>
          <material>
            <diffuse>0.125 0.125 0.125 1</diffuse>
            <ambient>0.125 0.125 0.125 1</ambient>
          </material>
        </visual>
      </link>
      <joint name='r_out_joint' type='revolute'>
        <pose relative_to='r_in_link'>0.00020426999999999999 0 0.028999 0 0 0</pose>
        <parent>r_in_link</parent>
        <child>r_out_link</child>
        <axis>
          <xyz>-0.99995999999999996 0.0046987000000000001 0.0070435999999999997</xyz>
          <mimic joint='r_joint'>
            <multiplier>1</multiplier>
            <offset>0</offset>
            <reference>0</reference>
          </mimic>
          <limit>
            <lower>-1.5700000000000001</lower>
            <upper>1.5700000000000001</upper>
            <effort>1000</effort>
            <velocity>10</velocity>
          </limit>
          <dynamics>
            <spring_reference>0</spring_reference>
            <spring_stiffness>0</spring_stiffness>
          </dynamics>
        </axis>
      </joint>
      <link name='r_out_link'>
        <pose relative_to='r_out_joint'>0 0 0 0 0 0</pose>
        <inertial>
          <pose>0.0060622000000000002 -0.0014473999999999999 0.0096106999999999998 0 0 0</pose>
          <mass>0.0038474</mass>
          <inertia>
            <ixx>8.7733999999999999e-07</ixx>
            <ixy>-1.2815e-09</ixy>
            <ixz>-6.7005999999999998e-09</ixz>
            <iyy>8.1956999999999997e-07</iyy>
            <iyz>-1.5634999999999999e-07</iyz>
            <izz>7.0760999999999994e-08</izz>
          </inertia>
        </inertial>
        <collision name='r_out_link_collision'>
          <pose>0 0 0 0 0 0</pose>
          <geometry>
            <mesh>
              <scale>1 1 1</scale>
              <uri>meshes_1/gripper/r_out_link.STL</uri>
            </mesh>
          </geometry>
        </collision>
        <visual name='r_out_link_visual'>
          <pose>0 0 0 0 0 0</pose>
          <geometry>
            <mesh>
              <scale>1 1 1</scale>
              <uri>meshes_1/gripper/r_out_link.STL</uri>
            </mesh>
          </geometry>
          <material>
            <diffuse>0.125 0.125 0.125 1</diffuse>
            <ambient>0.125 0.125 0.125 1</ambient>
          </material>
        </visual>
      </link>
      <joint name='r_joint' type='revolute'>
        <pose relative_to='link5'>-0.0073166000000000004 -0.013991999999999999 0.0324978 0 0 0</pose>
        <parent>link5</parent>
        <child>r_link</child>
        <axis>
          <xyz>0.99995999999999996 -0.0046990000000000001 -0.0070434</xyz>
          <limit>
            <lower>-1.5700000000000001</lower>
            <upper>1.5700000000000001</upper>
            <effort>1000</effort>
            <velocity>10</velocity>
          </limit>
          <dynamics>
            <spring_reference>0</spring_reference>
            <spring_stiffness>0</spring_stiffness>
          </dynamics>
        </axis>
      </joint>
      <link name='r_link'>
        <pose relative_to='r_joint'>0 0 0 0 0 0</pose>
        <inertial>
          <pose>0.0015465214258295801 0.00053411207047883403 0.0062403042812153604 0 0 0</pose>
          <mass>0.0020626564770486601</mass>
          <inertia>
            <ixx>3.9721584366934202e-07</ixx>
            <ixy>-2.7569912057938703e-10</ixy>
            <ixz>-2.1990104853612399e-09</ixz>
            <iyy>3.2247262734211502e-07</iyy>
            <iyz>1.07303783544668e-08</iyz>
            <izz>7.7870818667213105e-08</izz>
          </inertia>
        </inertial>
        <collision name='r_link_collision'>
          <pose>0 0 0 0 0 0</pose>
          <geometry>
            <mesh>
              <scale>1 1 1</scale>
              <uri>meshes_1/gripper/r_link.STL</uri>
            </mesh>
          </geometry>
        </collision>
        <visual name='r_link_visual'>
          <pose>0 0 0 0 0 0</pose>
          <geometry>
            <mesh>
              <scale>1 1 1</scale>
              <uri>meshes_1/gripper/r_link.STL</uri>
            </mesh>
          </geometry>
          <material>
            <diffuse>0.125 0.125 0.125 1</diffuse>
            <ambient>0.125 0.125 0.125 1</ambient>
          </material>
        </visual>
      </link>
      <frame name='back_shell_black_joint' attached_to='base_link'>
        <pose>-0.0080042302115637693 0.00018689841620892801 0 0 0 0</pose>
      </frame>
      <frame name='back_shell_black_link' attached_to='back_shell_black_joint'>
        <pose>0 0 0 0 0 0</pose>
      </frame>
      <frame name='back_shell_green_joint' attached_to='base_link'>
        <pose>-0.0080041999999999995 0.00018689999999999999 0 0 0 0</pose>
      </frame>
      <frame name='back_shell_green_link' attached_to='back_shell_green_joint'>
        <pose>0 0 0 0 0 0</pose>
      </frame>
      <frame name='imu_joint' attached_to='base_link'>
        <pose>0.0048415999999999997 0.011168000000000001 -0.0057397999999999998 3.1415926535897931 0 -1.5707963267948959</pose>
      </frame>
      <frame name='imu_link' attached_to='imu_joint'>
        <pose>0 0 0 0 0 0</pose>
      </frame>
      <frame name='lidar_joint' attached_to='base_link'>
        <pose>0.090003485935320399 0 0.040519577417955401 0 0 0</pose>
      </frame>
      <frame name='lidar_link' attached_to='lidar_joint'>
        <pose>0 0 0 0 0 0</pose>
      </frame>
      <frame name='wheel_left_back_joint' attached_to='base_link'>
        <pose>-0.0975130776687404 0.11212949919983201 -0.067841082157674606 0 0 0</pose>
      </frame>
      <frame name='wheel_left_back_link' attached_to='wheel_left_back_joint'>
        <pose>0 0 0 0 0 0</pose>
      </frame>
      <frame name='wheel_left_front_joint' attached_to='base_link'>
        <pose>0.097513076949966304 0.11212949984638999 -0.067841082157675106 0 0 0</pose>
      </frame>
      <frame name='wheel_left_front_link' attached_to='wheel_left_front_joint'>
        <pose>0 0 0 0 0 0</pose>
      </frame>
      <frame name='wheel_right_back_joint' attached_to='base_link'>
        <pose>-0.097513076949966998 -0.11212949984638999 -0.067841082157674398 0 0 0</pose>
      </frame>
      <frame name='wheel_right_back_link' attached_to='wheel_right_back_joint'>
        <pose>0 0 0 0 0 0</pose>
      </frame>
      <frame name='wheel_right_front_joint' attached_to='base_link'>
        <pose>0.097513077668739803 -0.11212949919983201 -0.067841082157674704 0 0 0</pose>
      </frame>
      <frame name='wheel_right_front_link' attached_to='wheel_right_front_joint'>
        <pose>0 0 0 0 0 0</pose>
      </frame>
      <frame name='base_joint' attached_to='base_footprint'>
        <pose>0 0 0.11609108215767459 0 0 0</pose>
      </frame>
      <frame name='base_link' attached_to='base_joint'>
        <pose>0 0 0 0 0 0</pose>
      </frame>
      <frame name='servo_joint1' attached_to='link1'>
        <pose>0 0 0 0 0 0</pose>
      </frame>
      <frame name='servo_link1' attached_to='servo_joint1'>
        <pose>0 0 0 0 0 0</pose>
      </frame>
      <frame name='depth_cam_joint_sim' attached_to='depth_cam_link'>
        <pose>0 0 0 -1.5707963267948959 -5.5511151231257827e-17 -1.5707963267948959</pose>
      </frame>
      <frame name='depth_cam_frame' attached_to='depth_cam_joint_sim'>
        <pose>0 0 0 0 0 0</pose>
      </frame>
      <frame name='depth_cam_joint' attached_to='camera_connect_link'>
        <pose>0 0 0.014475 1.570796326794897 -1.5707963267948966 0</pose>
      </frame>
      <frame name='depth_cam_link' attached_to='depth_cam_joint'>
        <pose>0 0 0 0 0 0</pose>
      </frame>
      <frame name='camera_connect_joint' attached_to='link4'>
        <pose>-0.050706026697764403 0 0.0505384841187764 0 0 -1.5707963267948899</pose>
      </frame>
      <frame name='camera_connect_link' attached_to='camera_connect_joint'>
        <pose>0 0 0 0 0 0</pose>
      </frame>
      <frame name='servo_joint2' attached_to='link4'>
        <pose>0 0 0.054483333950367398 0 0 0</pose>
      </frame>
      <frame name='servo_link2' attached_to='servo_joint2'>
        <pose>0 0 0 0 0 0</pose>
      </frame>
      <frame name='end_effector_joint' attached_to='link5'>
        <pose>0 0 0.080000000000000002 0 0 0</pose>
      </frame>
      <frame name='end_effector_link' attached_to='end_effector_joint'>
        <pose>0 0 0 0 0 0</pose>
      </frame>
      <frame name='gripper_joint' attached_to='link5'>
        <pose>0 0 0.0054387999999999997 0 0 0</pose>
      </frame>
      <frame name='gripper_link' attached_to='gripper_joint'>
        <pose>0 0 0 0 0 0</pose>
      </frame>

      <!-- Add physics plugins for the robot -->
      <plugin filename="gz-sim-joint-state-publisher-system" name="gz::sim::systems::JointStatePublisher">
        <joint_name>joint1</joint_name>
        <joint_name>joint2</joint_name>
        <joint_name>joint3</joint_name>
        <joint_name>joint4</joint_name>
        <joint_name>joint5</joint_name>
        <joint_name>r_joint</joint_name>
      </plugin>

      <!-- Differential drive plugin for mecanum wheels -->
      <plugin filename="gz-sim-diff-drive-system" name="gz::sim::systems::DiffDrive">
        <left_joint>wheel_left_front_joint</left_joint>
        <left_joint>wheel_left_back_joint</left_joint>
        <right_joint>wheel_right_front_joint</right_joint>
        <right_joint>wheel_right_back_joint</right_joint>
        <wheel_separation>0.224</wheel_separation>
        <wheel_radius>0.048</wheel_radius>
        <odom_publish_frequency>1</odom_publish_frequency>
        <topic>/cmd_vel</topic>
        <odom_topic>/odom</odom_topic>
        <frame_id>odom</frame_id>
        <child_frame_id>base_footprint</child_frame_id>
      </plugin>

      <!-- IMU sensor plugin -->
      <plugin filename="gz-sim-imu-system" name="gz::sim::systems::Imu">
        <link_name>base_footprint</link_name>
        <topic>/imu</topic>
      </plugin>

      <!-- Contact sensor to prevent falling through ground -->
      <plugin filename="gz-sim-contact-system" name="gz::sim::systems::Contact">
      </plugin>

    </model>
  </world>
</sdf>
