<sdf version='1.10'>
  <world name='WORKINGPROTO'>
    <physics name='1ms' type='ignored'>
      <max_step_size>0.001</max_step_size>
      <real_time_factor>1</real_time_factor>
      <real_time_update_rate>1000</real_time_update_rate>
    </physics>
    <plugin name='gz::sim::systems::Physics' filename='gz-sim-physics-system'/>
    <plugin name='gz::sim::systems::UserCommands' filename='gz-sim-user-commands-system'/>
    <plugin name='gz::sim::systems::SceneBroadcaster' filename='gz-sim-scene-broadcaster-system'/>
    <gravity>0 0 -9.8000000000000007</gravity>
    <magnetic_field>5.5644999999999998e-06 2.2875799999999999e-05 -4.2388400000000002e-05</magnetic_field>
    <atmosphere type='adiabatic'/>
    <scene>
      <ambient>0.400000006 0.400000006 0.400000006 1</ambient>
      <background>0.699999988 0.699999988 0.699999988 1</background>
      <shadows>true</shadows>
    </scene>
    <model name='ground_plane'>
      <static>true</static>
      <link name='link'>
        <collision name='collision'>
          <geometry>
            <plane>
              <normal>0 0 1</normal>
              <size>100 100</size>
            </plane>
          </geometry>
          <surface>
            <contact>
              <collide_bitmask>65535</collide_bitmask>
              <ode>
                <mu>100</mu>
                <mu2>50</mu2>
              </ode>
            </contact>
            <friction>
              <ode>
                <mu>100</mu>
                <mu2>50</mu2>
              </ode>
            </friction>
            <bounce/>
          </surface>
        </collision>
        <visual name='visual'>
          <cast_shadows>false</cast_shadows>
          <geometry>
            <plane>
              <normal>0 0 1</normal>
              <size>100 100</size>
            </plane>
          </geometry>
          <material>
            <ambient>0.800000012 0.800000012 0.800000012 1</ambient>
            <diffuse>0.800000012 0.800000012 0.800000012 1</diffuse>
            <specular>0 0 0 1</specular>
          </material>
        </visual>
        <pose>0 0 0 0 0 0</pose>
        <inertial>
          <pose>0 0 0 0 0 0</pose>
          <mass>1</mass>
          <inertia>
            <ixx>1</ixx>
            <ixy>0</ixy>
            <ixz>0</ixz>
            <iyy>1</iyy>
            <iyz>0</iyz>
            <izz>1</izz>
          </inertia>
        </inertial>
        <enable_wind>false</enable_wind>
      </link>
      <pose>0 0 0 0 0 0</pose>
      <self_collide>false</self_collide>
    </model>
    <model name='study_table'>
      <static>true</static>
      <pose>0 0 0 0 0 0</pose>
      <link name='table_link'>
        <inertial>
          <mass>50</mass>
          <inertia>
            <ixx>10</ixx>
            <iyy>8</iyy>
            <izz>6</izz>
            <ixy>0</ixy>
            <ixz>0</ixz>
            <iyz>0</iyz>
          </inertia>
          <pose>0 0 0 0 0 0</pose>
        </inertial>
        <visual name='table_top'>
          <pose>0 0 0.375 0 0 0</pose>
          <geometry>
            <box>
              <size>0.80000000000000004 0.59999999999999998 0.050000000000000003</size>
            </box>
          </geometry>
          <material>
            <ambient>0.800000012 0.600000024 0.400000006 1</ambient>
            <diffuse>0.800000012 0.600000024 0.400000006 1</diffuse>
          </material>
        </visual>
        <visual name='table_leg1'>
          <pose>0.34999999999999998 0.25 0.17499999999999999 0 0 0</pose>
          <geometry>
            <box>
              <size>0.10000000000000001 0.10000000000000001 0.34999999999999998</size>
            </box>
          </geometry>
          <material>
            <ambient>0.699999988 0.5 0.300000012 1</ambient>
            <diffuse>0.699999988 0.5 0.300000012 1</diffuse>
          </material>
        </visual>
        <visual name='table_leg2'>
          <pose>-0.34999999999999998 0.25 0.17499999999999999 0 0 0</pose>
          <geometry>
            <box>
              <size>0.10000000000000001 0.10000000000000001 0.34999999999999998</size>
            </box>
          </geometry>
          <material>
            <ambient>0.699999988 0.5 0.300000012 1</ambient>
            <diffuse>0.699999988 0.5 0.300000012 1</diffuse>
          </material>
        </visual>
        <visual name='table_leg3'>
          <pose>0.34999999999999998 -0.25 0.17499999999999999 0 0 0</pose>
          <geometry>
            <box>
              <size>0.10000000000000001 0.10000000000000001 0.34999999999999998</size>
            </box>
          </geometry>
          <material>
            <ambient>0.699999988 0.5 0.300000012 1</ambient>
            <diffuse>0.699999988 0.5 0.300000012 1</diffuse>
          </material>
        </visual>
        <visual name='table_leg4'>
          <pose>-0.34999999999999998 -0.25 0.17499999999999999 0 0 0</pose>
          <geometry>
            <box>
              <size>0.10000000000000001 0.10000000000000001 0.34999999999999998</size>
            </box>
          </geometry>
          <material>
            <ambient>0.699999988 0.5 0.300000012 1</ambient>
            <diffuse>0.699999988 0.5 0.300000012 1</diffuse>
          </material>
        </visual>
        <collision name='table_collision'>
          <pose>0 0 0.375 0 0 0</pose>
          <geometry>
            <box>
              <size>0.80000000000000004 0.59999999999999998 0.050000000000000003</size>
            </box>
          </geometry>
          <surface>
            <friction>
              <ode/>
            </friction>
            <bounce/>
            <contact/>
          </surface>
        </collision>
        <enable_wind>false</enable_wind>
        <pose>0 0 0 0 0 0</pose>
      </link>
      <self_collide>false</self_collide>
    </model>
    <model name='wall'>
      <static>true</static>
      <pose>0 0.28255310654640198 0.68000000715255737 0 0 0</pose>
      <link name='wall_link'>
        <inertial>
          <mass>20000000</mass>
          <inertia>
            <ixx>1.6699999999999999</ixx>
            <iyy>2.6699999999999999</iyy>
            <izz>1.0700000000000001</izz>
            <ixy>0</ixy>
            <ixz>0</ixz>
            <iyz>0</iyz>
          </inertia>
          <pose>0 0 0 0 0 0</pose>
        </inertial>
        <visual name='wall_base'>
          <pose>0 0 -0.14999999999999999 0 0 0</pose>
          <geometry>
            <box>
              <size>0.34999999999999998 0.050000000000000003 0.59999999999999998</size>
            </box>
          </geometry>
          <material>
            <ambient>0 0 1 1</ambient>
            <diffuse>0 0 1 1</diffuse>
          </material>
        </visual>
        <collision name='wall_base_collision'>
          <pose>0 0 -0.14999999999999999 0 0 0</pose>
          <geometry>
            <box>
              <size>0.34999999999999998 0.050000000000000003 0.59999999999999998</size>
            </box>
          </geometry>
          <surface>
            <friction>
              <ode/>
            </friction>
            <bounce/>
            <contact/>
          </surface>
        </collision>
        <enable_wind>false</enable_wind>
        <pose>0 0 0 0 0 0</pose>
      </link>
      <self_collide>false</self_collide>
    </model>
    <model name='tictactoe_game'>
      <static>false</static>
      <pose>-0.095263011753559126 -0.11987824738025665 0.41249999403953547 8.8383404893584834e-08 9.0853608459211234e-07 -0.00040046504296996913</pose>
      <link name='board'>
        <inertial>
          <mass>2</mass>
          <inertia>
            <ixx>0.10000000000000001</ixx>
            <iyy>0.10000000000000001</iyy>
            <izz>0.10000000000000001</izz>
            <ixy>0</ixy>
            <ixz>0</ixz>
            <iyz>0</iyz>
          </inertia>
          <pose>0 0 0 0 0 0</pose>
        </inertial>
        <visual name='board_visual'>
          <pose>0 0 0 0 0 0</pose>
          <geometry>
            <mesh>
              <scale>0.001 0.001 0.001</scale>
              <uri>file:///home/sukritchopra/ros2_ws/src/jetrover_description/models/jetrover/meshes_1/EXTERNAL_MESHES/tictactoe_board.stl</uri>
            </mesh>
          </geometry>
          <material>
            <ambient>1 1 1.20000001e-08 0.800000012</ambient>
            <diffuse>1 1 1.19999999e-09 0.800000012</diffuse>
          </material>
        </visual>
        <collision name='board_collision'>
          <pose>0 0 0 0 0 0</pose>
          <geometry>
            <mesh>
              <scale>0.001 0.001 0.001</scale>
              <uri>file:///home/sukritchopra/ros2_ws/src/jetrover_description/models/jetrover/meshes_1/EXTERNAL_MESHES/tictactoe_board.stl</uri>
            </mesh>
          </geometry>
          <surface>
            <friction>
              <ode/>
            </friction>
            <bounce/>
            <contact/>
          </surface>
        </collision>
        <enable_wind>false</enable_wind>
        <pose>0 0 0 0 0 0</pose>
      </link>
      <self_collide>false</self_collide>
    </model>
    <model name='o_piece_1'>
      <static>false</static>
      <pose>-0.14749899506568909 -0.15554991364479062 0.41499960297890465 0 0 0</pose>
      <link name='o_link'>
        <inertial>
          <mass>0.050000000000000003</mass>
          <inertia>
            <ixx>0.001</ixx>
            <iyy>0.001</iyy>
            <izz>0.001</izz>
            <ixy>0</ixy>
            <ixz>0</ixz>
            <iyz>0</iyz>
          </inertia>
          <pose>0 0 0 0 0 0</pose>
        </inertial>
        <visual name='o_visual'>
          <geometry>
            <sphere>
              <radius>0.014999999999999999</radius>
            </sphere>
          </geometry>
          <material>
            <ambient>0 0 0 1</ambient>
            <diffuse>0 0 0 1</diffuse>
          </material>
        </visual>
        <collision name='o_collision'>
          <geometry>
            <sphere>
              <radius>0.014999999999999999</radius>
            </sphere>
          </geometry>
          <surface>
            <friction>
              <ode/>
            </friction>
            <bounce/>
            <contact/>
          </surface>
        </collision>
        <pose>0 0 0 0 0 0</pose>
        <enable_wind>false</enable_wind>
      </link>
      <self_collide>false</self_collide>
    </model>
    <model name='o_piece_2'>
      <static>false</static>
      <pose>-0.14551700000000001 0.086727600000000002 0.41499960296575061 0 0 0</pose>
      <link name='o_link'>
        <inertial>
          <mass>0.050000000000000003</mass>
          <inertia>
            <ixx>0.001</ixx>
            <iyy>0.001</iyy>
            <izz>0.001</izz>
            <ixy>0</ixy>
            <ixz>0</ixz>
            <iyz>0</iyz>
          </inertia>
          <pose>0 0 0 0 0 0</pose>
        </inertial>
        <visual name='o_visual'>
          <geometry>
            <sphere>
              <radius>0.014999999999999999</radius>
            </sphere>
          </geometry>
          <material>
            <ambient>0 0 0 1</ambient>
            <diffuse>0 0 0 1</diffuse>
          </material>
        </visual>
        <collision name='o_collision'>
          <geometry>
            <sphere>
              <radius>0.014999999999999999</radius>
            </sphere>
          </geometry>
          <surface>
            <friction>
              <ode/>
            </friction>
            <bounce/>
            <contact/>
          </surface>
        </collision>
        <pose>0 0 0 0 0 0</pose>
        <enable_wind>false</enable_wind>
      </link>
      <self_collide>false</self_collide>
    </model>
    <model name='o_piece_3'>
      <static>false</static>
      <pose>-0.14555599999999999 -0.035008900000000003 0.41499960296575061 0 0 0</pose>
      <link name='o_link'>
        <inertial>
          <mass>0.050000000000000003</mass>
          <inertia>
            <ixx>0.001</ixx>
            <iyy>0.001</iyy>
            <izz>0.001</izz>
            <ixy>0</ixy>
            <ixz>0</ixz>
            <iyz>0</iyz>
          </inertia>
          <pose>0 0 0 0 0 0</pose>
        </inertial>
        <visual name='o_visual'>
          <geometry>
            <sphere>
              <radius>0.014999999999999999</radius>
            </sphere>
          </geometry>
          <material>
            <ambient>0 0 0 1</ambient>
            <diffuse>0 0 0 1</diffuse>
          </material>
        </visual>
        <collision name='o_collision'>
          <geometry>
            <sphere>
              <radius>0.014999999999999999</radius>
            </sphere>
          </geometry>
          <surface>
            <friction>
              <ode/>
            </friction>
            <bounce/>
            <contact/>
          </surface>
        </collision>
        <pose>0 0 0 0 0 0</pose>
        <enable_wind>false</enable_wind>
      </link>
      <self_collide>false</self_collide>
    </model>
    <model name='o_piece_4'>
      <static>false</static>
      <pose>-0.14728341996669772 -0.092032432556152344 0.41499960297890465 3.6146901355135932e-08 -1.4980699888930165e-08 1.7977899919169455e-06</pose>
      <link name='o_link'>
        <inertial>
          <mass>0.050000000000000003</mass>
          <inertia>
            <ixx>0.001</ixx>
            <iyy>0.001</iyy>
            <izz>0.001</izz>
            <ixy>0</ixy>
            <ixz>0</ixz>
            <iyz>0</iyz>
          </inertia>
          <pose>0 0 0 0 0 0</pose>
        </inertial>
        <visual name='o_visual'>
          <geometry>
            <sphere>
              <radius>0.014999999999999999</radius>
            </sphere>
          </geometry>
          <material>
            <ambient>0 0 0 1</ambient>
            <diffuse>0 0 0 1</diffuse>
          </material>
        </visual>
        <collision name='o_collision'>
          <geometry>
            <sphere>
              <radius>0.014999999999999999</radius>
            </sphere>
          </geometry>
          <surface>
            <friction>
              <ode/>
            </friction>
            <bounce/>
            <contact/>
          </surface>
        </collision>
        <pose>0 0 0 0 0 0</pose>
        <enable_wind>false</enable_wind>
      </link>
      <self_collide>false</self_collide>
    </model>
    <model name='o_piece_5'>
      <static>false</static>
      <pose>-0.14580499999999999 0.022861599999999999 0.41499960296575061 0 0 0</pose>
      <link name='o_link'>
        <inertial>
          <mass>0.050000000000000003</mass>
          <inertia>
            <ixx>0.001</ixx>
            <iyy>0.001</iyy>
            <izz>0.001</izz>
            <ixy>0</ixy>
            <ixz>0</ixz>
            <iyz>0</iyz>
          </inertia>
          <pose>0 0 0 0 0 0</pose>
        </inertial>
        <visual name='o_visual'>
          <geometry>
            <sphere>
              <radius>0.014999999999999999</radius>
            </sphere>
          </geometry>
          <material>
            <ambient>0 0 0 1</ambient>
            <diffuse>0 0 0 1</diffuse>
          </material>
        </visual>
        <collision name='o_collision'>
          <geometry>
            <sphere>
              <radius>0.014999999999999999</radius>
            </sphere>
          </geometry>
          <surface>
            <friction>
              <ode/>
            </friction>
            <bounce/>
            <contact/>
          </surface>
        </collision>
        <pose>0 0 0 0 0 0</pose>
        <enable_wind>false</enable_wind>
      </link>
      <self_collide>false</self_collide>
    </model>
    <model name='robot_box'>
      <static>true</static>
      <pose>0 0.21924400329589844 0.68879997730255127 1.5400002335725291 0 0</pose>
      <link name='box_link'>
        <inertial>
          <mass>5</mass>
          <inertia>
            <ixx>0.10000000000000001</ixx>
            <iyy>0.10000000000000001</iyy>
            <izz>0.10000000000000001</izz>
            <ixy>0</ixy>
            <ixz>0</ixz>
            <iyz>0</iyz>
          </inertia>
          <pose>0 0 0 0 0 0</pose>
        </inertial>
        <visual name='front_wall'>
          <pose>0.065000000000000002 0 0 0 0 0</pose>
          <geometry>
            <box>
              <size>0.01 0.13 0.105</size>
            </box>
          </geometry>
          <material>
            <ambient>0.600000024 0.400000006 0.200000003 1</ambient>
            <diffuse>0.600000024 0.400000006 0.200000003 1</diffuse>
          </material>
        </visual>
        <collision name='front_wall_collision'>
          <pose>0.065000000000000002 0 0 0 0 0</pose>
          <geometry>
            <box>
              <size>0.01 0.13 0.105</size>
            </box>
          </geometry>
          <surface>
            <friction>
              <ode/>
            </friction>
            <bounce/>
            <contact/>
          </surface>
        </collision>
        <visual name='back_wall'>
          <pose>-0.065000000000000002 0 0 0 0 0</pose>
          <geometry>
            <box>
              <size>0.01 0.13 0.105</size>
            </box>
          </geometry>
          <material>
            <ambient>0.600000024 0.400000006 0.200000003 1</ambient>
            <diffuse>0.600000024 0.400000006 0.200000003 1</diffuse>
          </material>
        </visual>
        <collision name='back_wall_collision'>
          <pose>-0.065000000000000002 0 0 0 0 0</pose>
          <geometry>
            <box>
              <size>0.01 0.13 0.105</size>
            </box>
          </geometry>
          <surface>
            <friction>
              <ode/>
            </friction>
            <bounce/>
            <contact/>
          </surface>
        </collision>
        <visual name='left_wall'>
          <pose>0 0.065000000000000002 0 0 0 0</pose>
          <geometry>
            <box>
              <size>0.13 0.01 0.105</size>
            </box>
          </geometry>
          <material>
            <ambient>0.600000024 0.400000006 0.200000003 1</ambient>
            <diffuse>0.600000024 0.400000006 0.200000003 1</diffuse>
          </material>
        </visual>
        <collision name='left_wall_collision'>
          <pose>0 0.065000000000000002 0 0 0 0</pose>
          <geometry>
            <box>
              <size>0.13 0.01 0.105</size>
            </box>
          </geometry>
          <surface>
            <friction>
              <ode/>
            </friction>
            <bounce/>
            <contact/>
          </surface>
        </collision>
        <visual name='right_wall'>
          <pose>0 -0.065000000000000002 0 0 0 0</pose>
          <geometry>
            <box>
              <size>0.13 0.01 0.105</size>
            </box>
          </geometry>
          <material>
            <ambient>0.600000024 0.400000006 0.200000003 1</ambient>
            <diffuse>0.600000024 0.400000006 0.200000003 1</diffuse>
          </material>
        </visual>
        <collision name='right_wall_collision'>
          <pose>0 -0.065000000000000002 0 0 0 0</pose>
          <geometry>
            <box>
              <size>0.13 0.01 0.105</size>
            </box>
          </geometry>
          <surface>
            <friction>
              <ode/>
            </friction>
            <bounce/>
            <contact/>
          </surface>
        </collision>
        <enable_wind>false</enable_wind>
        <pose>0 0 0 0 0 0</pose>
      </link>
      <self_collide>false</self_collide>
    </model>
    <model name='x_piece_1'>
      <static>false</static>
      <pose>0.16868799924850464 -0.091408386826515198 0.41499960297890465 0 0 0</pose>
      <link name='x_link'>
        <inertial>
          <mass>0.050000000000000003</mass>
          <inertia>
            <ixx>0.001</ixx>
            <iyy>0.001</iyy>
            <izz>0.001</izz>
            <ixy>0</ixy>
            <ixz>0</ixz>
            <iyz>0</iyz>
          </inertia>
          <pose>0 0 0 0 0 0</pose>
        </inertial>
        <visual name='x_visual'>
          <geometry>
            <sphere>
              <radius>0.014999999999999999</radius>
            </sphere>
          </geometry>
          <material>
            <ambient>1 1 1 0.800000012</ambient>
            <diffuse>1 1 1 0.800000012</diffuse>
          </material>
        </visual>
        <collision name='x_collision'>
          <geometry>
            <sphere>
              <radius>0.014999999999999999</radius>
            </sphere>
          </geometry>
          <surface>
            <friction>
              <ode/>
            </friction>
            <bounce/>
            <contact/>
          </surface>
        </collision>
        <pose>0 0 0 0 0 0</pose>
        <enable_wind>false</enable_wind>
      </link>
      <self_collide>false</self_collide>
    </model>
    <model name='x_piece_2'>
      <static>false</static>
      <pose>0.16940295696258545 0.10000000149011612 0.41499961827352366 0 0 0</pose>
      <link name='x_link'>
        <inertial>
          <mass>0.050000000000000003</mass>
          <inertia>
            <ixx>0.001</ixx>
            <iyy>0.001</iyy>
            <izz>0.001</izz>
            <ixy>0</ixy>
            <ixz>0</ixz>
            <iyz>0</iyz>
          </inertia>
          <pose>0 0 0 0 0 0</pose>
        </inertial>
        <visual name='x_visual'>
          <geometry>
            <sphere>
              <radius>0.014999999999999999</radius>
            </sphere>
          </geometry>
          <material>
            <ambient>1 1 1 0.800000012</ambient>
            <diffuse>1 1 1 0.800000012</diffuse>
          </material>
        </visual>
        <collision name='x_collision'>
          <geometry>
            <sphere>
              <radius>0.014999999999999999</radius>
            </sphere>
          </geometry>
          <surface>
            <friction>
              <ode/>
            </friction>
            <bounce/>
            <contact/>
          </surface>
        </collision>
        <pose>0 0 0 0 0 0</pose>
        <enable_wind>false</enable_wind>
      </link>
      <self_collide>false</self_collide>
    </model>
    <model name='x_piece_3'>
      <static>false</static>
      <pose>0.16690699756145477 0.04513685405254364 0.41499961827352366 0 0 0</pose>
      <link name='x_link'>
        <inertial>
          <mass>0.050000000000000003</mass>
          <inertia>
            <ixx>0.001</ixx>
            <iyy>0.001</iyy>
            <izz>0.001</izz>
            <ixy>0</ixy>
            <ixz>0</ixz>
            <iyz>0</iyz>
          </inertia>
          <pose>0 0 0 0 0 0</pose>
        </inertial>
        <visual name='x_visual'>
          <geometry>
            <sphere>
              <radius>0.014999999999999999</radius>
            </sphere>
          </geometry>
          <material>
            <ambient>1 1 1 0.800000012</ambient>
            <diffuse>1 1 1 0.800000012</diffuse>
          </material>
        </visual>
        <collision name='x_collision'>
          <geometry>
            <sphere>
              <radius>0.014999999999999999</radius>
            </sphere>
          </geometry>
          <surface>
            <friction>
              <ode/>
            </friction>
            <bounce/>
            <contact/>
          </surface>
        </collision>
        <pose>0 0 0 0 0 0</pose>
        <enable_wind>false</enable_wind>
      </link>
      <self_collide>false</self_collide>
    </model>
    <model name='x_piece_4'>
      <static>false</static>
      <pose>0.17164875566959381 -0.16792421042919159 0.41499913334545269 5.4253501679203851e-08 2.2626000502433425e-08 -5.9116098270073074e-07</pose>
      <link name='x_link'>
        <inertial>
          <mass>0.050000000000000003</mass>
          <inertia>
            <ixx>0.001</ixx>
            <iyy>0.001</iyy>
            <izz>0.001</izz>
            <ixy>0</ixy>
            <ixz>0</ixz>
            <iyz>0</iyz>
          </inertia>
          <pose>0 0 0 0 0 0</pose>
        </inertial>
        <visual name='x_visual'>
          <geometry>
            <sphere>
              <radius>0.014999999999999999</radius>
            </sphere>
          </geometry>
          <material>
            <ambient>1 1 1 0.800000012</ambient>
            <diffuse>1 1 1 0.800000012</diffuse>
          </material>
        </visual>
        <collision name='x_collision'>
          <geometry>
            <sphere>
              <radius>0.014999999999999999</radius>
            </sphere>
          </geometry>
          <surface>
            <friction>
              <ode/>
            </friction>
            <bounce/>
            <contact/>
          </surface>
        </collision>
        <pose>0 0 0 0 0 0</pose>
        <enable_wind>false</enable_wind>
      </link>
      <self_collide>false</self_collide>
    </model>
    <model name='x_piece_5'>
      <static>false</static>
      <pose>0.17582499980926514 -0.020129891112446785 0.41499961827352366 0 0 0</pose>
      <link name='x_link'>
        <inertial>
          <mass>0.050000000000000003</mass>
          <inertia>
            <ixx>0.001</ixx>
            <iyy>0.001</iyy>
            <izz>0.001</izz>
            <ixy>0</ixy>
            <ixz>0</ixz>
            <iyz>0</iyz>
          </inertia>
          <pose>0 0 0 0 0 0</pose>
        </inertial>
        <visual name='x_visual'>
          <geometry>
            <sphere>
              <radius>0.014999999999999999</radius>
            </sphere>
          </geometry>
          <material>
            <ambient>1 1 1 0.800000012</ambient>
            <diffuse>1 1 1 0.800000012</diffuse>
          </material>
        </visual>
        <collision name='x_collision'>
          <geometry>
            <sphere>
              <radius>0.014999999999999999</radius>
            </sphere>
          </geometry>
          <surface>
            <friction>
              <ode/>
            </friction>
            <bounce/>
            <contact/>
          </surface>
        </collision>
        <pose>0 0 0 0 0 0</pose>
        <enable_wind>false</enable_wind>
      </link>
      <self_collide>false</self_collide>
    </model>
    <model name='jetrover'>
      <pose>-0.0011388642577135227 0.25587814552580329 0.68266662672138945 1.5403072405840352 -0.041664810059215289 0.0025107026200145589</pose>
      <static>false</static>
      <self_collide>false</self_collide>
      <link name='base_footprint'>
        <inertial>
          <pose>0 0 0.0074999999999999997 0 0 0</pose>
          <mass>10000</mass>
          <inertia>
            <ixx>0.0015625000000000001</ixx>
            <ixy>0</ixy>
            <ixz>0</ixz>
            <iyy>0.0015625000000000001</iyy>
            <iyz>0</iyz>
            <izz>0.00125</izz>
          </inertia>
        </inertial>
        <collision name='base_footprint_collision'>
          <pose>0 0 0.037499999999999999 0 0 0</pose>
          <geometry>
            <cylinder>
              <radius>0.055</radius>
              <length>0.074999999999999997</length>
            </cylinder>
          </geometry>
          <surface>
            <friction>
              <ode/>
            </friction>
            <bounce/>
            <contact/>
          </surface>
        </collision>
        <visual name='base_footprint_visual'>
          <pose>0 0 0.037499999999999999 0 0 0</pose>
          <geometry>
            <cylinder>
              <radius>0.055</radius>
              <length>0.074999999999999983</length>
            </cylinder>
          </geometry>
          <material>
            <diffuse>0 1 0.400000006 1</diffuse>
            <ambient>0 1 0.400000006 1</ambient>
          </material>
        </visual>
        <enable_wind>false</enable_wind>
        <pose>0 0 0 0 0 0</pose>
      </link>
      <joint name='joint1' type='revolute'>
        <pose>1.0408340855860843e-17 1.0408340855860843e-17 4.163336342344337e-17 0 1.0587911840678754e-22 0</pose>
        <parent>base_footprint</parent>
        <child>link1</child>
        <axis>
          <xyz>-2.4651903288156619e-32 0 -1</xyz>
          <limit>
            <lower>-2.0899999999999999</lower>
            <upper>2.0899999999999999</upper>
            <effort>25</effort>
            <velocity>2</velocity>
            <stiffness>100000000</stiffness>
            <dissipation>1</dissipation>
          </limit>
          <dynamics>
            <spring_reference>0</spring_reference>
            <spring_stiffness>0</spring_stiffness>
            <damping>0.01</damping>
            <friction>0.01</friction>
          </dynamics>
        </axis>
      </joint>
      <link name='link1'>
        <pose>0.025132824221390068 -8.6886599803825959e-08 0.073493790589590546 2.3881846428759659e-07 -8.5819340913253558e-07 1.6892596769335295</pose>
        <inertial>
          <pose>8.4882317065151008e-05 -0.0018903126840200471 0.020339854275225711 0 0 0</pose>
          <mass>0.030629351759666201</mass>
          <inertia>
            <ixx>5.9254568915084221e-06</ixx>
            <ixy>-1.7073764982422979e-09</ixy>
            <ixz>1.179843003882826e-09</ixz>
            <iyy>5.2110986859518246e-06</iyy>
            <iyz>3.1259704103886081e-07</iyz>
            <izz>3.394062289608808e-06</izz>
          </inertia>
        </inertial>
        <collision name='link1_collision'>
          <pose>0 0 0 0 0 0</pose>
          <geometry>
            <mesh>
              <scale>1 1 1</scale>
              <uri>file:///home/sukritchopra/Gazebo Sims/meshes_1/arm/link1.STL</uri>
            </mesh>
          </geometry>
        </collision>
        <collision name='link1_fixed_joint_lump__servo_link1_collision_1'>
          <pose>0 0 0 0 0 0</pose>
          <geometry>
            <mesh>
              <scale>1 1 1</scale>
              <uri>file:///home/sukritchopra/Gazebo Sims/meshes_1/arm/servo_link1_collision.stl</uri>
            </mesh>
          </geometry>
        </collision>
        <visual name='link1_visual'>
          <pose>0 0 0 0 0 0</pose>
          <geometry>
            <mesh>
              <scale>1 1 1</scale>
              <uri>file:///home/sukritchopra/Gazebo Sims/meshes_1/arm/link1.STL</uri>
            </mesh>
          </geometry>
          <material>
            <diffuse>0.5 1 0.5 1</diffuse>
            <ambient>0.5 1 0.5 1</ambient>
          </material>
        </visual>
        <visual name='link1_fixed_joint_lump__servo_link1_visual_1'>
          <pose>0 0 0 0 0 0</pose>
          <geometry>
            <mesh>
              <scale>1 1 1</scale>
              <uri>file:///home/sukritchopra/Gazebo Sims/meshes_1/arm/servo_link1.STL</uri>
            </mesh>
          </geometry>
          <material>
            <diffuse>0.125 0.125 0.125 1</diffuse>
            <ambient>0.125 0.125 0.125 1</ambient>
          </material>
        </visual>
        <enable_wind>false</enable_wind>
      </link>
      <joint name='joint2' type='revolute'>
        <pose>-3.4694469519536142e-18 -1.0408340855860843e-17 6.9388939039072284e-17 2.7755575615628914e-17 -2.7755575615628914e-17 -3.8518598887744717e-34</pose>
        <parent>link1</parent>
        <child>link2</child>
        <axis>
          <xyz>5.5511151231257852e-17 1 -5.5511151231257827e-17</xyz>
          <limit>
            <lower>-2.0899999999999999</lower>
            <upper>2.0899999999999999</upper>
            <effort>30</effort>
            <velocity>1.5</velocity>
            <stiffness>100000000</stiffness>
            <dissipation>1</dissipation>
          </limit>
          <dynamics>
            <spring_reference>0</spring_reference>
            <spring_stiffness>0</spring_stiffness>
            <damping>0.01</damping>
            <friction>0.01</friction>
          </dynamics>
        </axis>
      </joint>
      <link name='link2'>
        <pose>0.025132835687047762 -1.1478962369526613e-07 0.10735859180604584 2.5125999129883276e-07 -0.31600844135705736 1.6892595988483787</pose>
        <inertial>
          <pose>0.00015629957042515699 -0.00045511369991391599 0.071772702851197495 0 0 0</pose>
          <mass>0.0329250074531705</mass>
          <inertia>
            <ixx>3.9162096617403702e-05</ixx>
            <ixy>-5.45461883923424e-11</ixy>
            <ixz>-1.84994427464167e-07</ixz>
            <iyy>3.0845356229789902e-05</iyy>
            <iyz>3.5881427402197002e-09</iyz>
            <izz>1.1508190097598299e-05</izz>
          </inertia>
        </inertial>
        <collision name='link2_collision'>
          <pose>0 0 0 0 0 0</pose>
          <geometry>
            <mesh>
              <scale>1 1 1</scale>
              <uri>file:///home/sukritchopra/Gazebo Sims/meshes_1/arm/link2_collision.stl</uri>
            </mesh>
          </geometry>
        </collision>
        <visual name='link2_visual'>
          <pose>0 0 0 0 0 0</pose>
          <geometry>
            <mesh>
              <scale>1 1 1</scale>
              <uri>file:///home/sukritchopra/Gazebo Sims/meshes_1/arm/link2.STL</uri>
            </mesh>
          </geometry>
          <material>
            <diffuse>0.5 1 0.5 1</diffuse>
            <ambient>0.5 1 0.5 1</ambient>
          </material>
        </visual>
        <enable_wind>false</enable_wind>
      </link>
      <joint name='joint3' type='revolute'>
        <pose>-8.6736173798840355e-17 -4.163336342344337e-17 1.1102230246251565e-16 0 0 0</pose>
        <parent>link2</parent>
        <child>link3</child>
        <axis>
          <xyz>-1.1102230246251565e-16 1 -1.7347234759768079e-18</xyz>
          <limit>
            <lower>-2.0899999999999999</lower>
            <upper>2.0899999999999999</upper>
            <effort>20</effort>
            <velocity>2.5</velocity>
            <stiffness>100000000</stiffness>
            <dissipation>1</dissipation>
          </limit>
          <dynamics>
            <spring_reference>0</spring_reference>
            <spring_stiffness>0</spring_stiffness>
            <damping>0.01</damping>
            <friction>0.01</friction>
          </dynamics>
        </axis>
      </joint>
      <link name='link3'>
        <pose>0.029886255282051504 -0.039937644032645436 0.23036678404369332 2.433884948521711e-07 -0.19409142022367309 1.6892596299901552</pose>
        <inertial>
          <pose>0.00012845644092569799 -0.00076142462273371704 0.071772743785429 0 0 0</pose>
          <mass>0.0329250074463074</mass>
          <inertia>
            <ixx>3.91621699579612e-05</ixx>
            <ixy>-5.4009753055806201e-11</ixy>
            <ixz>-1.7378665251201299e-07</ixz>
            <iyy>3.0845196992023903e-05</iyy>
            <iyz>3.6387423652222298e-09</iyz>
            <izz>1.15078234912494e-05</izz>
          </inertia>
        </inertial>
        <collision name='link3_collision'>
          <pose>0 0 0 0 0 0</pose>
          <geometry>
            <mesh>
              <scale>1 1 1</scale>
              <uri>file:///home/sukritchopra/Gazebo Sims/meshes_1/arm/link3_collision.stl</uri>
            </mesh>
          </geometry>
        </collision>
        <visual name='link3_visual'>
          <pose>0 0 0 0 0 0</pose>
          <geometry>
            <mesh>
              <scale>1 1 1</scale>
              <uri>file:///home/sukritchopra/Gazebo Sims/meshes_1/arm/link3.STL</uri>
            </mesh>
          </geometry>
          <material>
            <diffuse>0.5 1 0.5 1</diffuse>
            <ambient>0.5 1 0.5 1</ambient>
          </material>
        </visual>
        <enable_wind>false</enable_wind>
      </link>
      <joint name='joint4' type='revolute'>
        <pose>-5.2041704279304213e-18 2.7755575615628914e-17 -5.5511151231257827e-17 0 -1.3877787807814457e-17 0</pose>
        <parent>link3</parent>
        <child>link4</child>
        <axis>
          <xyz>-5.5511151231257827e-17 1 -6.9388939039072284e-17</xyz>
          <limit>
            <lower>-2.0899999999999999</lower>
            <upper>2.0899999999999999</upper>
            <effort>15</effort>
            <velocity>3</velocity>
            <stiffness>100000000</stiffness>
            <dissipation>1</dissipation>
          </limit>
          <dynamics>
            <spring_reference>0</spring_reference>
            <spring_stiffness>0</spring_stiffness>
            <damping>0.01</damping>
            <friction>0.01</friction>
          </dynamics>
        </axis>
      </joint>
      <link name='link4'>
        <pose>0.032837005039658904 -0.064729305241143842 0.35738087441723232 2.4252847550913394e-07 -0.17513630134398328 1.6892596346750042</pose>
        <inertial>
          <pose>-0.024155385718921799 0.0003017349751323721 0.048529459632962173 0 0 0</pose>
          <mass>0.034930330045039162</mass>
          <inertia>
            <ixx>3.5210229125809753e-05</ixx>
            <ixy>1.013027133785351e-07</ixy>
            <ixz>1.5667877911856121e-05</ixz>
            <iyy>5.5524620335933228e-05</iyy>
            <iyz>-6.19231011536335e-08</iyz>
            <izz>3.3657929512902879e-05</izz>
          </inertia>
        </inertial>
        <collision name='link4_collision'>
          <pose>0 0 0 0 0 0</pose>
          <geometry>
            <mesh>
              <scale>1 1 1</scale>
              <uri>file:///home/sukritchopra/Gazebo Sims/meshes_1/arm/link4_collision.stl</uri>
            </mesh>
          </geometry>
        </collision>
        <collision name='link4_fixed_joint_lump__camera_connect_link_collision_1'>
          <pose>-0.050706026697764403 0 0.0505384841187764 0 0 -1.5707963267948899</pose>
          <geometry>
            <mesh>
              <scale>1 1 1</scale>
              <uri>file:///home/sukritchopra/Gazebo Sims/meshes_1/arm/camera_connect_link.STL</uri>
            </mesh>
          </geometry>
        </collision>
        <collision name='link4_fixed_joint_lump__depth_cam_link_collision_2'>
          <pose>-0.050706026697764403 0 0.065013484118776402 6.9084068182086093e-15 -1.5707963267948966 0</pose>
          <geometry>
            <mesh>
              <scale>1 1 1</scale>
              <uri>file:///home/sukritchopra/Gazebo Sims/meshes_1/arm/depth_cam_link_collision.stl</uri>
            </mesh>
          </geometry>
        </collision>
        <collision name='link4_fixed_joint_lump__servo_link2_collision_3'>
          <pose>0 0 0.054483333950367398 0 0 0</pose>
          <geometry>
            <mesh>
              <scale>1 1 1</scale>
              <uri>file:///home/sukritchopra/Gazebo Sims/meshes_1/arm/servo_link2_collision.stl</uri>
            </mesh>
          </geometry>
        </collision>
        <visual name='link4_visual'>
          <pose>0 0 0 0 0 0</pose>
          <geometry>
            <mesh>
              <scale>1 1 1</scale>
              <uri>file:///home/sukritchopra/Gazebo Sims/meshes_1/arm/link4.STL</uri>
            </mesh>
          </geometry>
          <material>
            <diffuse>0.5 1 0.5 1</diffuse>
            <ambient>0.5 1 0.5 1</ambient>
          </material>
        </visual>
        <visual name='link4_fixed_joint_lump__camera_connect_link_visual_1'>
          <pose>-0.050706026697764403 0 0.0505384841187764 0 0 -1.5707963267948899</pose>
          <geometry>
            <mesh>
              <scale>1 1 1</scale>
              <uri>file:///home/sukritchopra/Gazebo Sims/meshes_1/arm/camera_connect_link.STL</uri>
            </mesh>
          </geometry>
          <material>
            <diffuse>0.125 0.125 0.125 1</diffuse>
            <ambient>0.125 0.125 0.125 1</ambient>
          </material>
        </visual>
        <visual name='link4_fixed_joint_lump__depth_cam_link_visual_2'>
          <pose>-0.050706026697764403 0 0.065013484118776402 6.9084068182086093e-15 -1.5707963267948966 0</pose>
          <geometry>
            <mesh>
              <scale>1 1 1</scale>
              <uri>file:///home/sukritchopra/Gazebo Sims/meshes_1/arm/depth_cam_link.STL</uri>
            </mesh>
          </geometry>
          <material>
            <diffuse>0.941250026 0.941250026 0.941250026 1</diffuse>
            <ambient>0.941250026 0.941250026 0.941250026 1</ambient>
          </material>
        </visual>
        <visual name='link4_fixed_joint_lump__servo_link2_visual_3'>
          <pose>0 0 0.054483333950367398 0 0 0</pose>
          <geometry>
            <mesh>
              <scale>1 1 1</scale>
              <uri>file:///home/sukritchopra/Gazebo Sims/meshes_1/arm/servo_link2.STL</uri>
            </mesh>
          </geometry>
          <material>
            <diffuse>0.125 0.125 0.125 1</diffuse>
            <ambient>0.125 0.125 0.125 1</ambient>
          </material>
        </visual>
        <enable_wind>false</enable_wind>
      </link>
      <joint name='joint5' type='revolute'>
        <pose>6.9388939039072284e-18 -1.1622647289044608e-16 5.5511151231257827e-17 0 0 0</pose>
        <parent>link4</parent>
        <child>link5</child>
        <axis>
          <xyz>-1.3877787807814457e-17 -2.5804011705155006e-17 -1</xyz>
          <limit>
            <lower>-2.0899999999999999</lower>
            <upper>2.0899999999999999</upper>
            <effort>8</effort>
            <velocity>4</velocity>
            <stiffness>100000000</stiffness>
            <dissipation>1</dissipation>
          </limit>
          <dynamics>
            <spring_reference>0</spring_reference>
            <spring_stiffness>0</spring_stiffness>
            <damping>0.01</damping>
            <friction>0.01</friction>
          </dynamics>
        </axis>
      </joint>
      <link name='link5'>
        <pose>0.033958997877729699 -0.074156073581702731 0.41103076583438242 0.16315387744387355 -0.063952331314548042 0.48878055711390767</pose>
        <inertial>
          <pose>0.013745583285676721 -0.0029797500659027461 0.029288990452975349 0 0 0</pose>
          <mass>0.01851660201761849</mass>
          <inertia>
            <ixx>4.8746350374566861e-06</ixx>
            <ixy>1.664776163181491e-08</ixy>
            <ixz>-3.9064646511571869e-07</ixz>
            <iyy>2.5142752233430748e-06</iyy>
            <iyz>1.050404679511314e-07</iyz>
            <izz>3.519823257486964e-06</izz>
          </inertia>
        </inertial>
        <collision name='link5_collision'>
          <pose>0 0 0 0 0 0</pose>
          <geometry>
            <mesh>
              <scale>1 1 1</scale>
              <uri>file:///home/sukritchopra/Gazebo Sims/meshes_1/arm/link5.STL</uri>
            </mesh>
          </geometry>
        </collision>
        <visual name='link5_visual'>
          <pose>0 0 0 0 0 0</pose>
          <geometry>
            <mesh>
              <scale>1 1 1</scale>
              <uri>file:///home/sukritchopra/Gazebo Sims/meshes_1/arm/link5.STL</uri>
            </mesh>
          </geometry>
          <material>
            <diffuse>0.125 0.125 0.125 1</diffuse>
            <ambient>0.125 0.125 0.125 1</ambient>
          </material>
        </visual>
        <enable_wind>false</enable_wind>
      </link>
      <link name='gripper_link'>
        <pose>0.034264370092293578 -0.075256113047042716 0.41631874872677399 0.16494387666698798 -0.064863257889286097 0.49454533394270478</pose>
        <inertial>
          <pose>0.014548183588905901 -0.00315257290321308 0.025349205371246099 0 0 0</pose>
          <mass>0.017498849031419399</mass>
          <inertia>
            <ixx>4.1261569268845601e-06</ixx>
            <ixy>-2.7510293906804899e-08</ixy>
            <ixz>-7.61180742281118e-09</ixz>
            <iyy>1.5702336531694299e-06</iyy>
            <iyz>2.2563082379695e-08</iyz>
            <izz>3.2612101868791e-06</izz>
          </inertia>
        </inertial>
        <collision name='gripper_link_collision'>
          <pose>0 0 0 0 0 0</pose>
          <geometry>
            <mesh>
              <scale>1 1 1</scale>
              <uri>file:///home/sukritchopra/Gazebo Sims/meshes_1/arm/gripper_link_collision.stl</uri>
            </mesh>
          </geometry>
        </collision>
        <visual name='gripper_link_visual'>
          <pose>0 0 0 0 0 0</pose>
          <geometry>
            <mesh>
              <scale>1 1 1</scale>
              <uri>file:///home/sukritchopra/Gazebo Sims/meshes_1/arm/gripper_link.STL</uri>
            </mesh>
          </geometry>
          <material>
            <diffuse>0.125 0.125 0.125 1</diffuse>
            <ambient>0.125 0.125 0.125 1</ambient>
          </material>
        </visual>
        <enable_wind>false</enable_wind>
      </link>
      <joint name='gripper_joint' type='fixed'>
        <parent>link5</parent>
        <child>gripper_link</child>
        <pose>-1.3877787807814457e-17 6.9388939039072284e-18 0 -2.688821387764051e-17 6.9388939039072284e-18 5.5511151231257827e-17</pose>
      </joint>
      <joint name='l_in_joint' type='fixed'>
        <pose>1.214306433183765e-17 6.0715321659188248e-17 0 -2.9490299091605721e-17 0 0</pose>
        <parent>gripper_link</parent>
        <child>l_in_link</child>
        <axis>
          <xyz>0.99996415378467485 0.0046983195165071984 -0.0070439292600142714</xyz>
          <limit>
            <lower>-1.5700000000000001</lower>
            <upper>1.5700000000000001</upper>
            <effort>8</effort>
            <velocity>1.5</velocity>
            <stiffness>100000000</stiffness>
            <dissipation>1</dissipation>
          </limit>
          <dynamics>
            <spring_reference>0</spring_reference>
            <spring_stiffness>0</spring_stiffness>
            <damping>0.29999999999999999</damping>
            <friction>0.14999999999999999</friction>
          </dynamics>
        </axis>
      </joint>
      <link name='l_in_link'>
        <pose>0.026610781252370801 -0.08243138814731632 0.46196293205263256 0.16494387666692595 -0.064863257889256273 0.49454533394270078</pose>
        <inertial>
          <pose>0.0061019181206524503 2.9145913289670801e-05 0.0144573768632076 0 0 0</pose>
          <mass>0.000776872870694597</mass>
          <inertia>
            <ixx>9.87455572181138e-08</ixx>
            <ixy>5.0634092847572699e-12</ixy>
            <ixz>-6.7968564625618604e-10</ixz>
            <iyy>9.7663514845220301e-08</iyy>
            <iyz>-6.1211590832379402e-12</iyz>
            <izz>2.2569536475165801e-09</izz>
          </inertia>
        </inertial>
        <collision name='l_in_link_collision'>
          <pose>0 0 0 0 0 0</pose>
          <geometry>
            <mesh>
              <scale>1 1 1</scale>
              <uri>file:///home/sukritchopra/Gazebo Sims/meshes_1/gripper/l_in_link.STL</uri>
            </mesh>
          </geometry>
        </collision>
        <visual name='l_in_link_visual'>
          <pose>0 0 0 0 0 0</pose>
          <geometry>
            <mesh>
              <scale>1 1 1</scale>
              <uri>file:///home/sukritchopra/Gazebo Sims/meshes_1/gripper/l_in_link.STL</uri>
            </mesh>
          </geometry>
          <material>
            <diffuse>0.125 0.125 0.125 1</diffuse>
            <ambient>0.125 0.125 0.125 1</ambient>
          </material>
        </visual>
        <enable_wind>false</enable_wind>
      </link>
      <joint name='l_out_joint' type='revolute'>
        <pose>0 1.1102230246251565e-16 0 0 -2.775557561562892e-17 0</pose>
        <parent>l_in_link</parent>
        <child>l_out_link</child>
        <axis>
          <xyz>0.99996415378467485 0.0046983195165071984 -0.0070439292600142436</xyz>
          <limit>
            <lower>-1.5700000000000001</lower>
            <upper>1.5700000000000001</upper>
            <effort>5</effort>
            <velocity>1</velocity>
            <stiffness>100000000</stiffness>
            <dissipation>1</dissipation>
          </limit>
          <dynamics>
            <spring_reference>0</spring_reference>
            <spring_stiffness>0</spring_stiffness>
            <damping>0.40000000000000002</damping>
            <friction>0.20000000000000001</friction>
          </dynamics>
        </axis>
      </joint>
      <link name='l_out_link'>
        <pose>0.027418194105267021 -0.087405713240884642 0.49052143169076734 0.93701163476562743 -0.059072906416442382 0.49187352913470772</pose>
        <inertial>
          <pose>0.0060240783651857701 0.0014461936314294 0.0096121404143418906 0 0 0</pose>
          <mass>0.0038473590828112399</mass>
          <inertia>
            <ixx>8.77337978935691e-07</ixx>
            <ixy>1.36760329013846e-09</ixy>
            <ixz>-6.9462127438421e-09</ixz>
            <iyy>8.1964879200802704e-07</iyy>
            <iyz>1.5617729472792301e-07</iyz>
            <izz>7.0687486597802998e-08</izz>
          </inertia>
        </inertial>
        <collision name='l_out_link_collision'>
          <pose>0 0 0 0 0 0</pose>
          <geometry>
            <mesh>
              <scale>1 1 1</scale>
              <uri>file:///home/sukritchopra/Gazebo Sims/meshes_1/gripper/l_out_link.STL</uri>
            </mesh>
          </geometry>
        </collision>
        <visual name='l_out_link_visual'>
          <pose>0 0 0 0 0 0</pose>
          <geometry>
            <mesh>
              <scale>1 1 1</scale>
              <uri>file:///home/sukritchopra/Gazebo Sims/meshes_1/gripper/l_out_link.STL</uri>
            </mesh>
          </geometry>
          <material>
            <diffuse>0.125 0.125 0.125 1</diffuse>
            <ambient>0.125 0.125 0.125 1</ambient>
          </material>
        </visual>
        <enable_wind>false</enable_wind>
      </link>
      <joint name='l_joint' type='revolute'>
        <pose>-6.9388939039072284e-18 1.1102230246251565e-16 -3.3306690738754696e-16 0 0 5.5511151231257815e-17</pose>
        <parent>gripper_link</parent>
        <child>l_link</child>
        <axis>
          <xyz>0.9999673742524674 0.0055810853450008512 -0.00583968466596214</xyz>
          <limit>
            <lower>-1.5700000000000001</lower>
            <upper>1.5700000000000001</upper>
            <effort>10</effort>
            <velocity>2</velocity>
            <stiffness>100000000</stiffness>
            <dissipation>1</dissipation>
          </limit>
          <dynamics>
            <spring_reference>0</spring_reference>
            <spring_stiffness>0</spring_stiffness>
            <damping>0.20000000000000001</damping>
            <friction>0.10000000000000001</friction>
          </dynamics>
        </axis>
      </joint>
      <link name='l_link'>
        <pose>0.021732738525346618 -0.07139702081442334 0.44476709761472083 0.83022162357081963 -0.05984062118841367 0.49293079277226726</pose>
        <inertial>
          <pose>0.0015384031888858 -0.00040323272684767401 0.00579759783012201 0 0 0</pose>
          <mass>0.0021892493318732202</mass>
          <inertia>
            <ixx>4.0534152698165002e-07</ixx>
            <ixy>3.6007782749450302e-10</ixy>
            <ixz>-1.99675888093364e-09</ixz>
            <iyy>3.3122217418185201e-07</iyy>
            <iyz>-8.7933775825091693e-09</iyz>
            <izz>7.7431958264291705e-08</izz>
          </inertia>
        </inertial>
        <collision name='l_link_collision'>
          <pose>0 0 0 0 0 0</pose>
          <geometry>
            <mesh>
              <scale>1 1 1</scale>
              <uri>file:///home/sukritchopra/Gazebo Sims/meshes_1/gripper/l_link.STL</uri>
            </mesh>
          </geometry>
        </collision>
        <visual name='l_link_visual'>
          <pose>0 0 0 0 0 0</pose>
          <geometry>
            <mesh>
              <scale>1 1 1</scale>
              <uri>file:///home/sukritchopra/Gazebo Sims/meshes_1/gripper/l_link.STL</uri>
            </mesh>
          </geometry>
          <material>
            <diffuse>0.125 0.125 0.125 1</diffuse>
            <ambient>0.125 0.125 0.125 1</ambient>
          </material>
        </visual>
        <enable_wind>false</enable_wind>
      </link>
      <joint name='r_in_joint' type='revolute'>
        <pose>-5.5511151231257827e-17 -5.5511151231257827e-17 1.1102230246251565e-16 -6.9388939039072284e-18 -5.5511151231257827e-17 1.9259299443872359e-34</pose>
        <parent>gripper_link</parent>
        <child>r_in_link</child>
        <axis>
          <xyz>-0.99996415401839334 0.0046987195192669962 0.0070436292604143299</xyz>
          <limit>
            <lower>-1.5700000000000001</lower>
            <upper>1.5700000000000001</upper>
            <effort>8</effort>
            <velocity>1.5</velocity>
            <stiffness>100000000</stiffness>
            <dissipation>1</dissipation>
          </limit>
          <dynamics>
            <spring_reference>0</spring_reference>
            <spring_stiffness>0</spring_stiffness>
            <damping>0.29999999999999999</damping>
            <friction>0.14999999999999999</friction>
          </dynamics>
        </axis>
      </joint>
      <link name='r_in_link'>
        <pose>0.031330623422538298 -0.090962523331536871 0.46034353671879769 0.96616621605754427 -0.065013342497129728 0.48793226634338271</pose>
        <inertial>
          <pose>0.0061019181206500598 -2.8192469006870501e-05 0.014457378753895699 0 0 0</pose>
          <mass>0.00077687287069452197</mass>
          <inertia>
            <ixx>9.8746566817120394e-08</ixx>
            <ixy>-5.1117380810663599e-12</ixy>
            <ixz>-6.7969240619170703e-10</ixz>
            <iyy>9.7664293636848998e-08</iyy>
            <iyz>-5.1401880014949702e-13</iyz>
            <izz>2.2571845877848701e-09</izz>
          </inertia>
        </inertial>
        <collision name='r_in_link_collision'>
          <pose>0 0 0 0 0 0</pose>
          <geometry>
            <mesh>
              <scale>1 1 1</scale>
              <uri>file:///home/sukritchopra/Gazebo Sims/meshes_1/gripper/r_in_link.STL</uri>
            </mesh>
          </geometry>
        </collision>
        <visual name='r_in_link_visual'>
          <pose>0 0 0 0 0 0</pose>
          <geometry>
            <mesh>
              <scale>1 1 1</scale>
              <uri>file:///home/sukritchopra/Gazebo Sims/meshes_1/gripper/r_in_link.STL</uri>
            </mesh>
          </geometry>
          <material>
            <diffuse>0.125 0.125 0.125 1</diffuse>
            <ambient>0.125 0.125 0.125 1</ambient>
          </material>
        </visual>
        <enable_wind>false</enable_wind>
      </link>
      <joint name='r_out_joint' type='revolute'>
        <pose>-2.0816681711721685e-17 -1.1102230246251565e-16 -1.1102230246251565e-16 -1.1102230246251565e-16 -2.7755575615628914e-17 1.5407439555097887e-33</pose>
        <parent>r_in_link</parent>
        <child>r_out_link</child>
        <axis>
          <xyz>-0.99996415401839334 0.0046987195192670726 0.0070436292604144201</xyz>
          <limit>
            <lower>-1.5700000000000001</lower>
            <upper>1.5700000000000001</upper>
            <effort>5</effort>
            <velocity>1</velocity>
            <stiffness>100000000</stiffness>
            <dissipation>1</dissipation>
          </limit>
          <dynamics>
            <spring_reference>0</spring_reference>
            <spring_stiffness>0</spring_stiffness>
            <damping>0.40000000000000002</damping>
            <friction>0.20000000000000001</friction>
          </dynamics>
        </axis>
      </joint>
      <link name='r_out_link'>
        <pose>0.04174924661502373 -0.11244276120174257 0.47680668948627103 2.5653846399296216 -0.053798626586529695 0.48327069363270753</pose>
        <inertial>
          <pose>0.0060622000000000002 -0.0014473999999999999 0.0096106999999999998 0 0 0</pose>
          <mass>0.0038474</mass>
          <inertia>
            <ixx>8.7733999999999999e-07</ixx>
            <ixy>-1.2815e-09</ixy>
            <ixz>-6.7005999999999998e-09</ixz>
            <iyy>8.1956999999999997e-07</iyy>
            <iyz>-1.5634999999999999e-07</iyz>
            <izz>7.0760999999999994e-08</izz>
          </inertia>
        </inertial>
        <collision name='r_out_link_collision'>
          <pose>0 0 0 0 0 0</pose>
          <geometry>
            <mesh>
              <scale>1 1 1</scale>
              <uri>file:///home/sukritchopra/Gazebo Sims/meshes_1/gripper/r_out_link.STL</uri>
            </mesh>
          </geometry>
        </collision>
        <visual name='r_out_link_visual'>
          <pose>0 0 0 0 0 0</pose>
          <geometry>
            <mesh>
              <scale>1 1 1</scale>
              <uri>file:///home/sukritchopra/Gazebo Sims/meshes_1/gripper/r_out_link.STL</uri>
            </mesh>
          </geometry>
          <material>
            <diffuse>0.125 0.125 0.125 1</diffuse>
            <ambient>0.125 0.125 0.125 1</ambient>
          </material>
        </visual>
        <enable_wind>false</enable_wind>
      </link>
      <joint name='r_joint' type='revolute'>
        <pose>4.8572257327350599e-17 -5.5511151231257827e-17 -2.7755575615628914e-17 0 0 0</pose>
        <parent>gripper_link</parent>
        <child>r_link</child>
        <axis>
          <xyz>0.99996415401743843 -0.0046990195205087642 -0.0070434292595768092</xyz>
          <limit>
            <lower>-1.5700000000000001</lower>
            <upper>1.5700000000000001</upper>
            <effort>10</effort>
            <velocity>2</velocity>
            <stiffness>100000000</stiffness>
            <dissipation>1</dissipation>
          </limit>
          <dynamics>
            <spring_reference>0</spring_reference>
            <spring_stiffness>0</spring_stiffness>
            <damping>0.20000000000000001</damping>
            <friction>0.10000000000000001</friction>
          </dynamics>
        </axis>
      </joint>
      <link name='r_link'>
        <pose>0.035105919269938252 -0.095531035650429197 0.44018750422361935 1.2833075440668416 -0.063647668800970336 0.4856300395490063</pose>
        <inertial>
          <pose>0.0015465214258295801 0.00053411207047883403 0.0062403042812153604 0 0 0</pose>
          <mass>0.0020626564770486601</mass>
          <inertia>
            <ixx>3.9721584366934202e-07</ixx>
            <ixy>-2.7569912057938703e-10</ixy>
            <ixz>-2.1990104853612399e-09</ixz>
            <iyy>3.2247262734211502e-07</iyy>
            <iyz>1.07303783544668e-08</iyz>
            <izz>7.7870818667213105e-08</izz>
          </inertia>
        </inertial>
        <collision name='r_link_collision'>
          <pose>0 0 0 0 0 0</pose>
          <geometry>
            <mesh>
              <scale>1 1 1</scale>
              <uri>file:///home/sukritchopra/Gazebo Sims/meshes_1/gripper/r_link.STL</uri>
            </mesh>
          </geometry>
        </collision>
        <visual name='r_link_visual'>
          <pose>0 0 0 0 0 0</pose>
          <geometry>
            <mesh>
              <scale>1 1 1</scale>
              <uri>file:///home/sukritchopra/Gazebo Sims/meshes_1/gripper/r_link.STL</uri>
            </mesh>
          </geometry>
          <material>
            <diffuse>0.125 0.125 0.125 1</diffuse>
            <ambient>0.125 0.125 0.125 1</ambient>
          </material>
        </visual>
        <enable_wind>false</enable_wind>
      </link>
      <frame name='base_joint' attached_to='base_footprint'>
        <pose>0 0 0.11609108215767459 0 0 0</pose>
      </frame>
      <frame name='base_link' attached_to='base_joint'>
        <pose>0 0 0 0 0 0</pose>
      </frame>
      <frame name='servo_joint1' attached_to='link1'>
        <pose>0 0 0 0 0 0</pose>
      </frame>
      <frame name='servo_link1' attached_to='servo_joint1'>
        <pose>0 0 0 0 0 0</pose>
      </frame>
      <frame name='depth_cam_joint_sim' attached_to='depth_cam_link'>
        <pose>0 0 0 -1.5707963267948959 -5.5511151231257827e-17 -1.5707963267948959</pose>
      </frame>
      <frame name='depth_cam_frame' attached_to='depth_cam_joint_sim'>
        <pose>0 0 0 0 0 0</pose>
      </frame>
      <frame name='depth_cam_joint' attached_to='camera_connect_link'>
        <pose>0 0 0.014475 1.5707963267948972 -1.5707963057214724 0</pose>
      </frame>
      <frame name='depth_cam_link' attached_to='depth_cam_joint'>
        <pose>0 0 0 0 0 0</pose>
      </frame>
      <frame name='camera_connect_joint' attached_to='link4'>
        <pose>-0.050706026697764403 0 0.0505384841187764 0 0 -1.5707963267948899</pose>
      </frame>
      <frame name='camera_connect_link' attached_to='camera_connect_joint'>
        <pose>0 0 0 0 0 0</pose>
      </frame>
      <frame name='servo_joint2' attached_to='link4'>
        <pose>0 0 0.054483333950367398 0 0 0</pose>
      </frame>
      <frame name='servo_link2' attached_to='servo_joint2'>
        <pose>0 0 0 0 0 0</pose>
      </frame>
      <frame name='end_effector_joint' attached_to='link5'>
        <pose>0 0 0.080000000000000002 0 0 0</pose>
      </frame>
      <frame name='end_effector_link' attached_to='end_effector_joint'>
        <pose>0 0 0 0 0 0</pose>
      </frame>
      <plugin name='gz::sim::systems::JointPositionController' filename='gz-sim-joint-position-controller-system'>
        <joint_name>joint1</joint_name>
        <initial_position>0.0</initial_position>
        <p_gain>80.0</p_gain>
        <i_gain>0.5</i_gain>
        <d_gain>15.0</d_gain>
      </plugin>
      <plugin name='gz::sim::systems::JointPositionController' filename='gz-sim-joint-position-controller-system'>
        <joint_name>joint2</joint_name>
        <initial_position>0.0</initial_position>
        <p_gain>120.0</p_gain>
        <i_gain>0.8</i_gain>
        <d_gain>20.0</d_gain>
      </plugin>
      <plugin name='gz::sim::systems::JointPositionController' filename='gz-sim-joint-position-controller-system'>
        <joint_name>joint3</joint_name>
        <initial_position>0.0</initial_position>
        <p_gain>60.0</p_gain>
        <i_gain>0.3</i_gain>
        <d_gain>12.0</d_gain>
      </plugin>
      <plugin name='gz::sim::systems::JointPositionController' filename='gz-sim-joint-position-controller-system'>
        <joint_name>joint4</joint_name>
        <initial_position>0.0</initial_position>
        <p_gain>35.0</p_gain>
        <i_gain>0.1</i_gain>
        <d_gain>8.0</d_gain>
      </plugin>
      <plugin name='gz::sim::systems::JointPositionController' filename='gz-sim-joint-position-controller-system'>
        <joint_name>joint5</joint_name>
        <initial_position>0.0</initial_position>
        <p_gain>25.0</p_gain>
        <i_gain>0.2</i_gain>
        <d_gain>5.0</d_gain>
      </plugin>
      <plugin name='gz::sim::systems::JointPositionController' filename='gz-sim-joint-position-controller-system'>
        <joint_name>r_joint</joint_name>
        <initial_position>0.0</initial_position>
        <p_gain>15.0</p_gain>
        <i_gain>0.02</i_gain>
        <d_gain>3.0</d_gain>
      </plugin>
    </model>
    <light name='sun' type='directional'>
      <pose>0 0 10 0 0 0</pose>
      <cast_shadows>true</cast_shadows>
      <intensity>1</intensity>
      <direction>-0.5 0.10000000000000001 -0.90000000000000002</direction>
      <diffuse>0.800000012 0.800000012 0.800000012 1</diffuse>
      <specular>0.200000003 0.200000003 0.200000003 1</specular>
      <attenuation>
        <range>1000</range>
        <linear>0.0099999997764825821</linear>
        <constant>0.89999997615814209</constant>
        <quadratic>0.0010000000474974513</quadratic>
      </attenuation>
      <spot>
        <inner_angle>0</inner_angle>
        <outer_angle>0</outer_angle>
        <falloff>0</falloff>
      </spot>
    </light>
  </world>
</sdf>
