<?xml version="1.0" ?>
<sdf version="1.6">
  <world name="default">
    
    <!-- Ground Plane -->
    <model name="ground_plane">
      <static>true</static>
      <link name="link">
        <collision name="collision">
          <geometry>
            <plane>
              <normal>0 0 1</normal>
              <size>100 100</size>
            </plane>
          </geometry>
        </collision>
        <visual name="visual">
          <geometry>
            <plane>
              <normal>0 0 1</normal>
              <size>100 100</size>
            </plane>
          </geometry>
          <material>
            <ambient>0.8 0.8 0.8 1</ambient>
            <diffuse>0.8 0.8 0.8 1</diffuse>
            <specular>0.8 0.8 0.8 1</specular>
          </material>
        </visual>
      </link>
    </model>

    <!-- Directional Light -->
    <light type="directional" name="sun">
      <cast_shadows>true</cast_shadows>
      <pose>0 0 10 0 0 0</pose>
      <diffuse>0.8 0.8 0.8 1</diffuse>
      <specular>0.2 0.2 0.2 1</specular>
      <attenuation>
        <range>1000</range>
        <constant>0.9</constant>
        <linear>0.01</linear>
        <quadratic>0.001</quadratic>
      </attenuation>
      <direction>-0.5 0.1 -0.9</direction>
    </light>

    <!-- Robot Model with Joint -->
    <model name="box_bot">
      <pose>0 0 0.5 0 0 0</pose>
      <link name="base_link">
        <pose>0 0 0 0 0 0</pose>
        <inertial>
          <mass>1.0</mass>
          <inertia>
            <ixx>0.01</ixx> <iyy>0.01</iyy> <izz>0.01</izz>
            <ixy>0.0</ixy> <ixz>0.0</ixz> <iyz>0.0</iyz>
          </inertia>
        </inertial>
        <collision name="collision">
          <geometry>
            <box>
              <size>0.5 0.5 0.2</size>
            </box>
          </geometry>
        </collision>
        <visual name="visual">
          <geometry>
            <box>
              <size>0.5 0.5 0.2</size>
            </box>
          </geometry>
        </visual>
      </link>

      <link name="wheel_link">
        <pose>0.3 0 0 0 0 0</pose>
        <inertial>
          <mass>0.5</mass>
          <inertia>
            <ixx>0.005</ixx> <iyy>0.005</iyy> <izz>0.005</izz>
            <ixy>0.0</ixy> <ixz>0.0</ixz> <iyz>0.0</iyz>
          </inertia>
        </inertial>
        <collision name="collision">
          <geometry>
            <cylinder>
              <radius>0.1</radius>
              <length>0.05</length>
            </cylinder>
          </geometry>
        </collision>
        <visual name="visual">
          <geometry>
            <cylinder>
              <radius>0.1</radius>
              <length>0.05</length>
            </cylinder>
          </geometry>
        </visual>
      </link>

      <!-- Revolute Joint -->
      <joint name="wheel_joint" type="revolute">
        <parent>base_link</parent>
        <child>wheel_link</child>
        <pose>0.25 0 0 0 0 0</pose>
        <axis>
          <xyz>0 1 0</xyz>
          <limit>
            <lower>-3.14</lower>
            <upper>3.14</upper>
          </limit>
          <dynamics>
            <damping>0.1</damping>
          </dynamics>
        </axis>
      </joint>
    </model>

    <!-- Physics -->
    <physics name="default_physics" type="ode">
      <max_step_size>0.001</max_step_size>
      <real_time_factor>1.0</real_time_factor>
    </physics>

    <!-- Plugins -->
    <plugin filename="gz-sim-physics-system"
            name="gz::sim::systems::Physics" />

    <plugin filename="gz-sim-user-commands-system"
            name="gz::sim::systems::UserCommands" />

    <plugin filename="gz-sim-scene-broadcaster-system"
            name="gz::sim::systems::SceneBroadcaster" />

    <plugin filename="gz-sim-sensors-system"
            name="gz::sim::systems::Sensors">
      <render_engine>ogre2</render_engine>
    </plugin>

    <plugin filename="gz-sim-joint-state-publisher-system"
            name="gz::sim::systems::JointStatePublisher">
      <topic>joint_states</topic>
      <joint_name>wheel_joint</joint_name>
    </plugin>

  </world>
</sdf>
